Workbook
Name ㅁ1: '[1]`98지침'!#REF!
Name ㅁ1: '[1]`98지침'!#REF!
Name ㅁ1: '[1]`98지침'!#REF!
Name ㅁ1: '[1]`98지침'!#REF!
Name ㅁ1: '[1]`98지침'!#REF!
Name ㅁ1: '[1]`98지침'!#REF!
Name ㅁ1: '[1]`98지침'!#REF!
Name ㅁ1: '[1]`98지침'!#REF!
Name ㅁ1: '[1]`98지침'!#REF!
Name ㅁ1: '[1]`98지침'!#REF!
Name ㅁ1: '[1]`98지침'!#REF!
Name ㅁ1: '[1]`98지침'!#REF!
Name ㅁ1: '[1]`98지침'!#REF!
Name ㅁ1: '[1]`98지침'!#REF!
Name ㅁ1: '[1]`98지침'!#REF!
Name ㅁ1: '[1]`98지침'!#REF!

Sheet DROPDOWN_LIST
A1: 아차사고선택목록
A2: {=_xlfn._xlws.FILTER(near_miss_excel_view__2[제목] & " / " & TEXT(near_miss_excel_view__2[발생일시],"yyyy-mm-dd"), near_miss_excel_view__2[제목]<>"")} -> 우수 맨홀 뚜껑 밀림으로 전도 / 2025-01-09
A3: 사다리에 손가락 끼임 / 2025-03-11
A4: 작업중 위에서 떨어지는 낙화물 / 2025-03-18
A5: 케이블 포설 중 요통발생 / 2025-03-21
A6: 호이스트 강제개방 고장 및 추락위험 / 2025-03-26
A7: 전기실 악세스플로어가 내려앉으면서 발이빠짐 / 2025-03-28
A8: 세트앙카에 안전모가 부딪힐 뻔 함. / 2025-04-07
A9: 야간 작업시 시야확보에 따른 찰과상 / 2025-04-15
A10: 고소차량 탑승 전 안전난간 설치 중 손가락이 끼일 뻔 함 / 2025-05-07
A11: 바닥에 있는 설비배관에 발이 걸려 넘어질 뻔함 / 2025-05-07
A12: TR 운반 중 바닥이 미끄러워 넘어질 뻔 함 / 2025-05-14
A13: 크레인 케이블 수리하는 중 상부 구조물에 머리를 부딪힐 뻔함 / 2025-05-30
A14: 케이블을 무리하게 당기다가 근육통 발생함 / 2025-06-12
... A69: 3호 IDF 필터 빼다가 뒤로 넘어갈뻔 했습니다 / 2026-05-12

Sheet near_miss_excel_view
A1: 보고서ID | B1: 작성자명 | C1: 제목 | D1: 발생일시 | E1: 발생장소 | F1: 내용 | G1: 원인 | H1: 사고유형 | I1: 불안전한 상태 | J1: 불안전한 행동 | K1: 부주의한 행동 | L1: 부주의한 상태 | M1: 즉시조치 | N1: 재발방지대책
A2: 1 | B2: 이후민 | C2: 우수 맨홀 뚜껑 밀림으로 전도 | D2: 45666.389 | E2: 4P34 전기실 앞 | F2: 우수 맨홀 뚜껑이 고정되지 않아 밟았을 때 맨홀이 움직여 미끄러짐 | G2: 불안전한 상태: 개구부 불안전한 행동: 기타 부주의 행동: 위험을 보지 않음 부주의 상태: 서두름 | H2: 전도 | I2: 개구부 | J2: 기타 | K2: 위험을 보지 않음 | L2: 서두름 | M2: 맨홀 주위에 접근 금지 표시를 설치하여 사고 재발생을 예방함 | N2: 맨홀 주위에 접근 금지 표시를 설치하여 사고 재발생을 예방함
A3: 3 | B3: 김남균 | C3: 사다리에 손가락 끼임 | D3: 45727.551 | E3: #4 cooler | F3: 사다리를 접다가 손가락 끼임 | G3: 불안전한 상태: 도구 및 장비 불안전한 행동: 도구의 잘못 사용 부주의 행동: 위험을 생각하지 않음 부주의 상태: 서두름 | H3: 협착 | I3: 도구 및 장비 | J3: 도구의 잘못 사용 | K3: 위험을 생각하지 않음 | L3: 서두름 | M3: 사다리를 접기 전에 항상 주의하도록 교육 | N3: 사다리를 접기 전에 항상 주의하도록 교육
A4: 5 | B4: 김도담 | C4: 작업중 위에서 떨어지는 낙화물 | D4: 45734.594 | E4: 2호 kiln inlet 2층 | F4: 상층 작업자 용접으로 인한 용접 불티가 떨어지는 위험 | G4: 불안전한 상태: 낙석 불안전한 행동: 보호구 부주의 행동: 위험을 보지 않음 부주의 상태: 서두름 | H4: 화상/동상 | I4: 낙석 | J4: 보호구 | K4: 위험을 보지 않음 | L4: 서두름 | M4: 보호구 착용과 용접이 끝난후 안전하게 작업 | N4: 보호구 착용과 용접이 끝난후 안전하게 작업
A5: 2 | B5: 김민규 | C5: 케이블 포설 중 요통발생 | D5: 45737.59 | E5: 풍력선별기 | F5: 케이블 포설 중 협소공간에서 불안정한 자세로 인해 요통발생 | G5: 불안전한 상태: 통로 불안전한 행동: 불안전한 자세 부주의 행동: 몸의 균형이 불안정해짐 부주의 상태: 서두름 | H5: 요통 | I5: 통로 | J5: 불안전한 자세 | K5: 몸의 균형이 불안정해짐 | L5: 서두름 | M5: 충분한 작업 공간을 확보한 후 작업 중간에 쉬는 시간을 가짐 | N5: 충분한 작업 공간을 확보한 후 작업 중간에 쉬는 시간을 가짐
A6: 4 | B6: 서용주 | C6: 호이스트 강제개방 고장 및 추락위험 | D6: 45742.462 | E6: 한라 구내 4호기 | F6: #4 2층 INLET 알리막리프트의 관성에 의해 하차위치와 리프트위치의 단차가 발생해 넘어질뻔 함 | G6: 불안전한 상태: 설비 불안전한 행동: 기타 부주의 행동: 위험경로에 위치함 부주의 상태: 서두름 | H6: 전도 | I6: 설비 | J6: 기타 | K6: 위험경로에 위치함 | L6: 서두름 | M6: CCR 통보하여 수리 | N6: CCR 통보하여 수리
A7: 6 | B7: 정원석 | C7: 전기실 악세스플로어가 내려앉으면서 발이빠짐 | D7: 45744.396 | E7: 풍력선별기 2P7 전기실 | F7: 케이블 포설을 위해 악세스플로어를 열어놨고 지지대가 제대로 받쳐주지 않은 곳에 발을 딛다가 밑으로 발이 빠져 다칠뻔 함 | G7: 불안전한 상태: 작업발판 불안전한 행동: 평소 습관 부주의 행동: 위험을 생각하지 않음 부주의 상태: 서두름 | H7: 전도 | I7: 작업발판 | J7: 평소 습관 | K7: 위험을 생각하지 않음 | L7: 서두름 | M7: 지지대 재설치 후 다른 작업 인원에게도 위험하다고 알림 | N7: 지지대 재설치 후 다른 작업 인원에게도 위험하다고 알림
A8: 7 | B8: 김민규 | C8: 세트앙카에 안전모가 부딪힐 뻔 함. | D8: 45754.375 | E8: 항만 석회석 치장 내 | F8: 전자해머 점검용 워크웨이를 올라가기 위해 수직사다리를 통해 올라가던 중 상부 천장에 노출된 미사용 셋트앙카에 안전모가 살짝 부딪힘 먼저 이동 경로를 확인 하고 위험요소를 발견 후 이동하여야 하는데 발견하지 못함 | G8: 불안전한 상태: 통로 불안전한 행동: 평소 습관 부주의 행동: 위험을 보지 않음 부주의 상태: 서두름 | H8: 기타 | I8: 통로 | J8: 평소 습관 | K8: 위험을 보지 않음 | L8: 서두름 | M8: 삽입 된 셋트앙카를 제거 후 안전한지 확인하고 이동함. | N8: 삽입 된 셋트앙카를 제거 후 안전한지 확인하고 이동함.
A9: 8 | B9: 김도담 | C9: 야간 작업시 시야확보에 따른 찰과상 | D9: 45762.083 | E9: 2호 KILM INLET | F9: 야간 근무 시 2호 INLET 주변 전등이 안 들어와 이동하다 넘어짐 | G9: 불안전한 상태: 전기 불안전한 행동: 불안전한 자세 부주의 행동: 위험경로에 위치함 부주의 상태: 서두름 | H9: 절단/ 찰과상 | I9: 전기 | J9: 불안전한 자세 | K9: 위험경로에 위치함 | L9: 서두름 | M9: 생산근무자에게 야간 작업등을 항상 켜 놓으라 전달 | N9: 생산근무자에게 야간 작업등을 항상 켜 놓으라 전달
A10: 10 | B10: 윤순형 | C10: 고소차량 탑승 전 안전난간 설치 중 손가락이 끼일 뻔 함 | D10: 45784.09 | E10: 광산 초소 | F10: 사다리차 탑승 전 안전난간을 조립하던 과정에 난간판넬 접힘부에 손가락이 끼일 뻔함 차례대로 접어야 하는데 한꺼번에 접으려다 손가락이 접힘부에 있었는지 망각함. | G10: 불안전한 상태: 도구 및 장비 불안전한 행동: 도구의 잘못 사용 부주의 행동: 위험을 보지 않음 부주의 상태: 서두름 | H10: 협착 | I10: 도구 및 장비 | J10: 도구의 잘못 사용 | K10: 위험을 보지 않음 | L10: 서두름 | M10: 주변동료에게 알림. | N10: 주변동료에게 알림.
A11: 11 | B11: 윤택천 | C11: 바닥에 있는 설비배관에 발이 걸려 넘어질 뻔함 | D11: 45784.375 | E11: Roll Press Hydro Pump Room | F11: 케이블 포설을 마지고 이동 중 설비 배관에 발이 걸려 넘어질 뻔 함 | G11: 불안전한 상태: 통로 불안전한 행동: 평소 습관 부주의 행동: 위험을 보지 않음 부주의 상태: 서두름 | H11: 전도 | I11: 통로 | J11: 평소 습관 | K11: 위험을 보지 않음 | L11: 서두름 | M11: 주변 동료에게 공유함. | N11: 주변 동료에게 공유함.
A12: 12 | B12: 정원석 | C12: TR 운반 중 바닥이 미끄러워 넘어질 뻔 함 | D12: 45791.594 | E12: 항만 알루미나 전기실 | F12: 교체할 TR을 지정된 위치로 밀어서 이동 중 바닥의 물기로 인해 미끄러질 뻔 함. / 이동동선의 물기를 확이하지 않음. | G12: 불안전한 상태: 조명/ 환경 불안전한 행동: 평소 습관 부주의 행동: 위험을 보지 않음 부주의 상태: 피로 | H12: 전도 | I12: 조명/ 환경 | J12: 평소 습관 | K12: 위험을 보지 않음 | L12: 피로 | M12: 작은 물기라도 무거운 물체를 밀고 있을때는 미끄러울 수 있다는 것을 주변 동료와 공유함. | N12: 작은 물기라도 무거운 물체를 밀고 있을때는 미끄러울 수 있다는 것을 주변 동료와 공유함.
A13: 13 | B13: 엄기준 | C13: 크레인 케이블 수리하는 중 상부 구조물에 머리를 부딪힐 뻔함 | D13: 45807.628 | E13: 항만공작실 | F13: 좁은공간에서 작업을 마치고 일어나는 순간 상부 배관에 부딪힐 뻔함/ 상부에 배관이 지나가고 있다는 것을 일어나면서 알아챔. | G13: 불안전한 상태: 작업발판 불안전한 행동: 불안전한 자세 부주의 행동: 위험을 생각하지 않음 부주의 상태: 피로 | H13: 충돌 | I13: 작업발판 | J13: 불안전한 자세 | K13: 위험을 생각하지 않음 | L13: 피로 | M13: 좁은 공간에서 몸을 움직일 때는 항상 이동하려는 곳을 먼저 육안으로 확인 후 이동할 것을 주변동료와 공유함. | N13: 좁은 공간에서 몸을 움직일 때는 항상 이동하려는 곳을 먼저 육안으로 확인 후 이동할 것을 주변동료와 공유함.
... A37: 35 | B37: 김남균 | C37: 구조물에 안전모 부딪힘 | D37: 46042.375 | E37: 320갱 BC3 | F37: 트레이 거치대 작업을 위해 컨베이어 하부로 이동 중 안전모가 구조물에 부딪힘 / 부주의 | G37: 불안전한 상태: 통로 불안전한 행동: 평소 습관 부주의 행동: 위험을 보지 않음 부주의 상태: 서두름 | H37: 충돌 | I37: 통로 | J37: 평소 습관 | K37: 위험을 보지 않음 | L37: 서두름 | M37: TBM 위험성 평가때 동료들과 공유 | N37: TBM 위험성 평가때 동료들과 공유
A38: 39 | B38: 박재민 | C38: 계단 이동중 미끄러짐 | D38: 46043.635 | E38: 2호 프로브 계단 | F38: 계단쪽에 물이 있어서 미끄러 잡아질뻔했습니다 날씨가 추운탓도 있고 계단이 얼어서 미끄럽습니다 | G38: 불안전한 상태: - 불안전한 행동: - 부주의 행동: - 부주의 상태: - | M38: 기존 데이터 이관 | N38: 기존 데이터 이관
A39: 37 | B39: 김도담 | C39: 미끄러짐 | D39: 46044.424 | E39: 2k inlet | F39: 이동중 살얼음에 미끄러짐 | G39: 불안전한 상태: 폭설/ 결빙 불안전한 행동: 불안전한 자세 부주의 행동: 몸의 균형이 불안정해짐 부주의 상태: 자만심 | H39: 절단/ 찰과상 | I39: 폭설/ 결빙 | J39: 불안전한 자세 | K39: 몸의 균형이 불안정해짐 | L39: 자만심 | M39: 이동시 바닥을 확인하여 이동하였습니다 | N39: 이동시 바닥을 확인하여 이동하였습니다
A40: 36 | B40: 한윤근 | C40: 리프트에서 내릴때 작업발판 접지름 | D40: 46047.406 | E40: 4k 리프트 | F40: 리프트와 작업발판 사이 단차로 생긴 사고 | G40: 불안전한 상태: 작업발판 불안전한 행동: 불안전한 자세 부주의 행동: 위험을 생각하지 않음 부주의 상태: 서두름 | H40: 기타 | I40: 작업발판 | J40: 불안전한 자세 | K40: 위험을 생각하지 않음 | L40: 서두름 | M40: 발목보호되는 안전화 착용 및 내릴때 한번더 확인후 이동하겠습니다. | N40: 발목보호되는 안전화 착용 및 내릴때 한번더 확인후 이동하겠습니다.
A41: 40 | B41: 이정민 | C41: 계단 미끄러짐 | D41: 46050.472 | E41: 3호 2층 전기실 올라가는 계단 | F41: 2층 전기실로 가는 계단에서 1층으로 내려가던 중 계단에서 미끄러짐 / 계단에 칸이 작고 오래되어 미끄러움 | G41: 불안전한 상태: 작업발판 불안전한 행동: 기타 부주의 행동: 위험을 보지 않음 부주의 상태: 서두름 | H41: 기타 | I41: 작업발판 | J41: 기타 | K41: 위험을 보지 않음 | L41: 서두름 | M41: 앞으로 이동시 손잡이를 잡고 이동하겠습니다 | N41: 앞으로 이동시 손잡이를 잡고 이동하겠습니다
A42: 45 | B42: 김남균 | C42: 고드름 낙하 | D42: 46066.583 | E42: 320갱 111-BC3구간 | F42: 이동 중 상부 고드름이 낙하하여 맞을 뻔함. / 일부 미제거 된 고드름 | G42: 불안전한 상태: 통로 불안전한 행동: 기타 부주의 행동: 위험을 보지 않음 부주의 상태: 서두름 | H42: 낙하 | I42: 통로 | J42: 기타 | K42: 위험을 보지 않음 | L42: 서두름 | M42: 주의 깊게 관찰하며 고드름 제거 하겠습니다. | N42: 주의 깊게 관찰하며 고드름 제거 하겠습니다.
A43: 41 | B43: 이정민 | C43: 낙하물 | D43: 46076.438 | E43: 광산 320갱 | F43: 광산 320갱 트레이 설치 중 떨어져있던 볼트나 너트류 다리에 걸려 밑으로 떨어짐 | G43: 불안전한 상태: 통로 불안전한 행동: 기타 부주의 행동: 위험을 보지 않음 부주의 상태: 서두름 | H43: 낙하 | I43: 통로 | J43: 기타 | K43: 위험을 보지 않음 | L43: 서두름 | M43: 주변에 떨어져있던 낙하물들을 청소 밑 정리 조치 하였습니다 | N43: 주변에 떨어져있던 낙하물들을 청소 밑 정리 조치 하였습니다
A44: 42 | B44: 김도담 | C44: 낙하물에 의한 위험 | D44: 46076.463 | E44: 2호 klin | F44: 위에서 떨어진 낙화물에 다칠뻔함 | G44: 불안전한 상태: 기타 불안전한 행동: 기타 부주의 행동: 위험을 보지 않음 부주의 상태: 자만심 | H44: 낙하 | I44: 기타 | J44: 기타 | K44: 위험을 보지 않음 | L44: 자만심 | M44: 항상 다닐때 작업장 주의를 살피고 있습니다 | N44: 항상 다닐때 작업장 주의를 살피고 있습니다
A45: 43 | B45: 장진혁 | C45: 이젝터 부품 해체 중 손이 주변 구조물에 부딪침 | D45: 46077.549 | E45: 3호 kiln inlet | F45: 3호 kiln inlet에서 이젝터 부품을 스패너로 해체하던 중 주변 구조물에 손이 부딪침/작업 중 동선 파악을 제대로 못함 | G45: 불안전한 상태: 도구 및 장비 불안전한 행동: 평소 습관 부주의 행동: 위험을 생각하지 않음 부주의 상태: 서두름 | H45: 충돌 | I45: 도구 및 장비 | J45: 평소 습관 | K45: 위험을 생각하지 않음 | L45: 서두름 | M45: 주변 동선 파악 후 작업 | N45: 주변 동선 파악 후 작업
A46: 44 | B46: 한윤근 | C46: 계단 이동중 상부구조물 충돌 | D46: 46077.928 | E46: 4호기 2층 | F46: inlet probe 작업하러 계단 오르던중 상부 구조물 충돌 | G46: 불안전한 상태: 조명/ 환경 불안전한 행동: 불안전한 자세 부주의 행동: 위험을 보지 않음 부주의 상태: 서두름 | H46: 충돌 | I46: 조명/ 환경 | J46: 불안전한 자세 | K46: 위험을 보지 않음 | L46: 서두름 | M46: 야간 작업중 계단 오를시 헤드라이트로 구조물 미리식별후 안전하게 이동하겠습니다. | N46: 야간 작업중 계단 오를시 헤드라이트로 구조물 미리식별후 안전하게 이동하겠습니다.
A47: 48 | B47: 정재호 | C47: 프로브 조립시 수공구에 의한 찍힘 | D47: 46091.792 | E47: 협력업체 작업장 | F47: 프로브 조립 중 스패너 조임 작업도중 체결을 확실히 못하고 돌리는 사고가 발생 | G47: 불안전한 상태: 기타 불안전한 행동: 도구의 잘못 사용 부주의 행동: 위험을 보지 않음 부주의 상태: 서두름 | H47: 기타 | I47: 기타 | J47: 도구의 잘못 사용 | K47: 위험을 보지 않음 | L47: 서두름 | M47: 앞으로 프로브 조립 및 스패너 사용 작업시 체결유무 확실히 확인 후 작업 하겠습니다 | N47: 앞으로 프로브 조립 및 스패너 사용 작업시 체결유무 확실히 확인 후 작업 하겠습니다
A48: 47 | B48: 김도담 | C48: 공구 사용하다 찰과상 | D48: 46092.417 | E48: 4k kiln inlet | F48: 볼트 체결중 힘을주고 몽키 돌리다 풀리면서 손가락 다칠뻔함 | G48: 불안전한 상태: 도구 및 장비 불안전한 행동: 도구의 잘못 사용 부주의 행동: 몸의 균형이 불안정해짐 부주의 상태: 서두름 | H48: 절단/ 찰과상 | I48: 도구 및 장비 | J48: 도구의 잘못 사용 | K48: 몸의 균형이 불안정해짐 | L48: 서두름 | M48: 헐거워진 몽키에 기름칠을 해도 위험해보여 몽키를 구입해서 사용함 | N48: 헐거워진 몽키에 기름칠을 해도 위험해보여 몽키를 구입해서 사용함
A49: 46 | B49: 박재민 | C49: 야간작업시 계단올라갔을때 넘어짐 | D49: 46093.062 | E49: 4k INLET (PROBE )있는장소 | F49: 야간에현장자체가 어두컴컴하고 아무리 후레쉬를 켜도 시야가 뿌옇고 먼지 쌓인 장소에서 작업을 하다보니 시야가 앞을 가려서 조심해서 올라간다는 생각을 하고 올라갔는데 넘어졌습니다 | G49: 불안전한 상태: 계단 불안전한 행동: 평소 습관 부주의 행동: 위험경로에 위치함 부주의 상태: 피로 | H49: 충돌 | I49: 계단 | J49: 평소 습관 | K49: 위험경로에 위치함 | L49: 피로 | M49: 작업을 하기전에 항상 위험요소물이 있는지 확인하고 계단올라갔을시 조심해서 작업을 하겠습니다 | N49: 작업을 하기전에 항상 위험요소물이 있는지 확인하고 계단올라갔을시 조심해서 작업을 하겠습니다
A50: 60 | B50: 이돈희 | C50: 그라인더 사용중 불티 화상 | D50: 46103.329 | E50: 320갱 | F50: 그라인더 사용중. 불티가 티어서 눈에 화상 입음 | G50: 안전보호구 착용 했음 에도. 제가 부주의 하여 불꽃팀 | H50: 화상/동상 | I50: 설비 | J50: 불안전한 자세 | K50: 위험을 생각하지 않음 | L50: 기타 | M50: 그라인더 불티방지 사용
A51: 49 | B51: 한지민 | C51: 소통 미비로 결선 중 단락 사고 발생할 뻔 함. | D51: 46106.674 | E51: 320갱 전기실 부근 | F51: 선임 작업자가 결선 전 단계 까지만 하라고 전달했지만 제대로 전달되지 않아 결선까지 하게 됨. | G51: 불안전한 상태: 전기 불안전한 행동: 소통 미비 부주의 행동: 위험을 생각하지 않음 부주의 상태: 서두름 | H51: 감전 | I51: 전기 | J51: 소통 미비 | K51: 위험을 생각하지 않음 | L51: 서두름 | M51: 위험성이 있는 작업은 절대 임의로 판단하에 작업 금지, 무전으로 작업해도 괜찮다고 연락 받아도 마지막으로 검전기 혹은 테스터기로 확인 후 작업 하도록 교육 및 숙지 | N51: 위험성이 있는 작업은 절대 임의로 판단하에 작업 금지, 무전으로 작업해도 괜찮다고 연락 받아도 마지막으로 검전기 혹은 테스터기로 확인 후 작업 하도록 교육 및 숙지
A52: 50 | B52: 이정민 | C52: 440V 감전사고 | D52: 46107.625 | E52: 광산현대화 전기실 | F52: 440V 케이블 결선 중 파워가 죽지 않았는데 결선을 하려고하여 쇼트사고 | G52: 불안전한 상태: 전기 불안전한 행동: 소통 미비 부주의 행동: 위험을 보지 않음 부주의 상태: 서두름 | H52: 감전 | I52: 전기 | J52: 소통 미비 | K52: 위험을 보지 않음 | L52: 서두름 | M52: 서두르지 않고 절연장갑을 착용 후 결선작업 진행 | N52: 서두르지 않고 절연장갑을 착용 후 결선작업 진행
A53: 51 | B53: 이정민 | C53: 습기에 의한 미끄러짐 | D53: 46107.625 | E53: 광산현대화 전기실 | F53: 바닥의 물기를 보지 않고 이동 중 미끄러짐 | G53: 불안전한 상태: 통로 불안전한 행동: 평소 습관 부주의 행동: 위험을 보지 않음 부주의 상태: 서두름 | H53: 전도 | I53: 통로 | J53: 평소 습관 | K53: 위험을 보지 않음 | L53: 서두름 | M53: 서두르지 않고 바닥을 확인 후 이동하겠음 | N53: 서두르지 않고 바닥을 확인 후 이동하겠음
A54: 52 | B54: 윤순형 | C54: 나무 가시에 찔림 | D54: 46110.542 | E54: 집 | F54: 나무 전지 작업 중 가시에 찔림/ 보호구(안전장갑) 미착용 | G54: 불안전한 상태: 도구 및 장비 불안전한 행동: 평소 습관 부주의 행동: 위험을 보지 않음 부주의 상태: 서두름 | H54: 기타 | I54: 도구 및 장비 | J54: 평소 습관 | K54: 위험을 보지 않음 | L54: 서두름 | M54: 일상생활에서도 안전습관화 되도록 숙지 및 경험담 전파. | N54: 일상생활에서도 안전습관화 되도록 숙지 및 경험담 전파.
A55: 55 | B55: 박재민 | C55: 계단에서 미끄러짐 | D55: 46113.854 | E55: 4호 프로브 계단실 | F55: 계단턱에 걸리거나 미끄러져서 바닥에 몸이 부딪힘 | G55: 이동 시 난간을 잡지 않고 빠른 속도로 이동함. | H55: 전도 | I55: 안전난간 | J55: 기타 | K55: 몸의 균형이 불안정해짐 | L55: 피로 | M55: 서두르지 않고 작업을 하겠습니다 | N55: 서두르지 않고 작업을 하겠습니다
A56: 54 | B56: 장진혁 | C56: 4호 inlet 이젝터 청소 작업 중 이젝터 나사가 바닥에 떨어짐, 나사를 찾으려다 바닥에 넘어질뻔함 | D56: 46114.41 | E56: 4호 kiln inlet | F56: 4k inlet 이젝터 청소를 하다 바닥에 나사가 떨어짐, 나사를 찾으려 움직이다 바닥에 넘어질 뻔함 | G56: 바닥 근처에 공구가방이 있었는데 나사를 찾으려다 확인하지 못함 | H56: 전도 | I56: 정리정돈 | J56: 불안전한 자세 | K56: 위험경로에 위치함 | L56: 서두름 | M56: 주변 동선 확인 후 작업 | N56: 주변 동선 확인 후 작업
A57: 53 | B57: 김도담 | C57: 공구 사용하다 칠과상 | D57: 46115.379 | E57: 4k kiln inlet | F57: 파이브렌치를 사용하다 헛돌아 넘어짐 | G57: 공구를 체결 시 손잡이와 파이프가 수직상태에 놓이지 않은 상태로, 몸의 위치가 손잡이 중심선에서 많이 벗어난 상태였음 | H57: 절단/찰과상 | I57: 도구 및 장비 | J57: 불안전한 자세 | K57: 몸의 균형이 불안정해짐 | L57: 서두름 | M57: 급하게 작업하기보단 공구가 체결된거 확인후<br>안전하게 작업 | N57: 급하게 작업하기보단 공구가 체결된거 확인후_x000D_ 안전하게 작업
A58: 114 | B58: 이정민 | C58: 판넬 이송 중 머리 부딪힘 | D58: 46125.34 | E58: 현대기전 사무실 | F58: 판넬을 사무실 밖으로 빼기 위해 구르마로 이동 중 사무실 문 앞 턱에서 판넬이 기울어지며 넘어감 그 후 넘어가는 쪽에 있던 인원이 머리를 부딪힘. | G58: 서두르다가 이동경로의 장애물을 생각하지 못함. | H58: 전도 | I58: 통로 | J58: 불안전한 자세 | K58: 위험경로에 위치함 | L58: 자만심 | M58: 사용했던 구르마보다 큰 규격의 구르마를 사용하고 판넬을 세워서 이동하지 않고 눕혀서 2명 이상의 인원이 함께 작업을 하였습니다. | N58: 사용했던 구르마보다 큰 규격의 구르마를 사용하고 판넬을 세워서 이동하지 않고 눕혀서 2명 이상의 인원이 함께 작업을 하였습니다.
A59: 115 | B59: 이정민 | C59: 광산현대화 BC2 벨트에서 이동식 비계를 옮기던 중 미끄러짐 | D59: 46125.431 | E59: 광산 320갱 BC2벨트 | F59: BC2벨트 구조물 위에 안착해놨던 이동식 비계를 CRUSHER방향으로 테스트 겸 밀던 중 벨트위에 고여있던 물들과 부석들이 발에 걸리며 미끄러질뻔함. | G59: 이동하기 전에 이동경로에 장애물이 있는지 사전 조사실시 미흡. | H59: 전도 | I59: 통로 | J59: 기타: 무거운 짐 취급 | K59: 몸의 균형이 불안정해짐 | L59: 서두름 | M59: 고여있던 물들을 벨트를 꾹 눌러 밑으로 흘려보내고 부석들도 땅으로 밀어 치워둠 | N59: 고여있던 물들을 벨트를 꾹 눌러 밑으로 흘려보내고 부석들도 땅으로 밀어 치워둠
A60: 59 | B60: 이정민 | C60: 그라인더 작업 중 쉿가루 튐 | D60: 46127.438 | E60: 광산 bc2 벨트 | F60: 트레이 작업 중 그라인더로 잔넬을 절단하던 중 쉿가루가 눈으로 튐 | G60: 눈에는 보안경을 착용하고 있었지만 자르는 행위 중 아래를 보면서 작업을 해야했고 보안경이 조금씩 흘러내리는 사이 눈으로 튐 | H60: 유해물질 접촉 | I60: 기타 | J60: 불안전한 자세 | K60: 위험을 생각하지 않음 | L60: 자만심 | M60: 보안경을 바르게 착용하고 내 자세를 딱 고정할 수 있는 위치에서 작업시행
A61: 116 | B61: 정재호 | C61: 사다리 이동중 무릎, 팔 타박상 | D61: 46128.958 | E61: 4호 coal mill probe 위치 | F61: 야간에 사다리 이동 중 부딪힘 | G61: 조도가 낮은 상태에서 주변 확인을 하지 못함 | H61: 충돌 | I61: 돌출부 | J61: 기타 | K61: 몸의 균형이 불안정해짐 | L61: 서두름 | M61: 야간작업중 사다리 이동 시 해드랜턴 항시 켜놓은 후 돌출부 확인 및 접지 부 확인 철저 | N61: 야간작업중 사다리 이동 시 해드랜턴 항시 켜놓은 후 돌출부 확인 및 접지 부 확인 철저
A62: 58 | B62: 이윤성 | C62: 4k kiln inlet 계단 올라갈 때 배관에 헬멧 박아서 계단에서 넘어질 뻔함 | D62: 46130.944 | E62: 4k kiln inlet 앞 계단 | F62: 4k kiln inlet Probe 점검하러 올라가려는 계단에 위치한 배관에 헬멧을 박아서 뒤로 넘어질 뻔한 사고 발생 | G62: 계단 위치에 있는 배관이 너무 낮게 되어 있습니다. | H62: 충돌 | I62: 계단 | J62: 불안전한 자세 | K62: 위험을 생각하지 않음 | L62: 서두름 | M62: 재발을 방지하기 위해 헤드 라이트를 사용 후 고개와 허리를 숙이며 안전 난간을 잡고 조심히 이동하였습니다.
A63: 118 | B63: 김동훈 | C63: 작업중 부딪침. | D63: 46140.976 | E63: 2호 IDF PROBE 앞. | F63: IDF 펌프 및 라인 청소 중 조도 문제로 바닥 구조물에 부딪치고 넘어질 뻔 함. | G63: 작업중 부주의하여 부딪침. | H63: 충돌 | I63: 조명/환경 | J63: 기타: 부주의 | K63: 위험을 생각하지 않음 | L63: 서두름 | M63: 작업 중 부주의가 원인으로 구조물이 있는 동선에서 작업 하지 않도록 함.
...

Sheet 보고서(4-01)
B1: (■ 아차사고 , □ 응급처치 ) 보고서
A3: ■ 아차사고 보고서를 이용하여, 상황이 다소 달랐다면 인명피해로 이어질수 있었던 사고를 보고해 주시기 바랍니다
A4: ■ 여러분의 협조가 당사의 인적, 물적 피해를 줄일 수 있으며 예방하는 도움이 됩니다
H5: ="작성일 : "&TEXT(_xlfn.XLOOKUP(B7,near_miss_excel_view!C:C,near_miss_excel_view!D:D,"없음",0,1),"YY-MM-DD") -> 작성일 : 26-04-01
A6: 소 속 | B6: 현대기전 | D6: 성 명 | E6: =_xlfn.XLOOKUP(B7,near_miss_excel_view!C:C,near_miss_excel_view!B:B,"없음",0,1) -> 박재민 | G6: 사 번
A7: 아차사고명 | B7: 계단에서 미끄러짐
A9: 아차사고 | B9: =" 1. 발생 일시 : "&TEXT(_xlfn.XLOOKUP(B7,near_miss_excel_view!C:C,near_miss_excel_view!D:D,"없음",0,1),"YYYY년 MM월 DD일 hh시 mm분")&" 경" -> 1. 발생 일시 : 2026년 04월 01일 20시 30분 경
A10: 경험(목격) | B10: =" 2. 발생 장소 : "&_xlfn.XLOOKUP(B7,near_miss_excel_view!C:C,near_miss_excel_view!E:E,"없음",0,1) -> 2. 발생 장소 : 4호 프로브 계단실
A11: 내용 및 | B11: {=" 3. 내용 / 원인 : "&_xlfn.XLOOKUP(B7,near_miss_excel_view!C:C,CHAR(10)&"내용: "&near_miss_excel_view!F:F&CHAR(10)&"원인: "&near_miss_excel_view!G:G,"없음",0,1)} -> 3. 내용 / 원인 : 내용: 계단턱에 걸리거나 미끄러져서 바닥에 몸이 부딪힘 원인: 이동 시 난간을 잡지 않고 빠른 속도로 이동함. | J11: 보고서ID
A12: 원인 입니다 | J12: 55
J16: 사고유형 | L16: 불안전한상태 | N16: 불안전한행동 | P16: 부주의 행동 | R16: 부주의 상태
A17: 다음 해당하는 사항에 체크하세요. | J17: =_xlfn.XLOOKUP(B7,near_miss_excel_view!$C:$C,near_miss_excel_view!H:H,"없음",0,1) -> 전도 | L17: =_xlfn.XLOOKUP(B7,near_miss_excel_view!$C:$C,near_miss_excel_view!I:I,"없음",0,1) -> 안전난간 | N17: =_xlfn.XLOOKUP(B7,near_miss_excel_view!$C:$C,near_miss_excel_view!J:J,"없음",0,1) -> 기타 | P17: =_xlfn.XLOOKUP(B7,near_miss_excel_view!$C:$C,near_miss_excel_view!K:K,"없음",0,1) -> 몸의 균형이 불안정해짐 | R17: =_xlfn.XLOOKUP(B7,near_miss_excel_view!$C:$C,near_miss_excel_view!L:L,"없음",0,1) -> 피로
A18: 사고 유형 | D18: 불안전한 상태 :
J19: 추락 | K19: =IF(J19=$J$17,TRUE,FALSE) -> FALSE | L19: 통로 | M19: =IF($L$17=L19,TRUE,FALSE) -> FALSE | N19: 규정위반 | O19: =IF($N$17=N19,TRUE,FALSE) -> FALSE | P19: 위험경로에 위치함 | Q19: =IF($P$17=P19,TRUE,FALSE) -> FALSE | R19: 서두름 | S19: =IF($R$17=R19,TRUE,FALSE) -> FALSE
J20: 전도 | K20: =IF(J20=$J$17,TRUE,FALSE) -> TRUE | L20: 돌출부 | M20: =IF($L$17=L20,TRUE,FALSE) -> FALSE | N20: 도구의 잘못 사용 | O20: =IF($N$17=N20,TRUE,FALSE) -> FALSE | P20: 몸의 균형이 불안정해짐 | Q20: =IF($P$17=P20,TRUE,FALSE) -> TRUE | R20: 피로 | S20: =IF($R$17=R20,TRUE,FALSE) -> TRUE
J21: 충돌 | K21: =IF(J21=$J$17,TRUE,FALSE) -> FALSE | L21: 안전난간 | M21: =IF($L$17=L21,TRUE,FALSE) -> TRUE | N21: 무거운 짐 취급 | O21: =IF($N$17=N21,TRUE,FALSE) -> FALSE | P21: 위험을 보지 않음 | Q21: =IF($P$17=P21,TRUE,FALSE) -> FALSE | R21: 스트레스 | S21: =IF($R$17=R21,TRUE,FALSE) -> FALSE
J22: 낙하 | K22: =IF(J22=$J$17,TRUE,FALSE) -> FALSE | L22: 작업발판 | M22: =IF($L$17=L22,TRUE,FALSE) -> FALSE | N22: 보호구 | O22: =IF($N$17=N22,TRUE,FALSE) -> FALSE | P22: 위험을 생각하지 않음 | Q22: =IF($P$17=P22,TRUE,FALSE) -> FALSE | R22: 자만심 | S22: =IF($R$17=R22,TRUE,FALSE) -> FALSE
J23: 비래 | K23: =IF(J23=$J$17,TRUE,FALSE) -> FALSE | L23: 개구부 | M23: =IF($L$17=L23,TRUE,FALSE) -> FALSE | N23: 불안전한 자세 | O23: =IF($N$17=N23,TRUE,FALSE) -> FALSE
J24: 붕괴 | K24: =IF(J24=$J$17,TRUE,FALSE) -> FALSE | L24: 전기 | M24: =IF($L$17=L24,TRUE,FALSE) -> FALSE | N24: 소통 미비 | O24: =IF($N$17=N24,TRUE,FALSE) -> FALSE
J25: 협착 | K25: =IF(J25=$J$17,TRUE,FALSE) -> FALSE | L25: 운전장비 | M25: =IF($L$17=L25,TRUE,FALSE) -> FALSE | N25: 평소 습관 | O25: =IF($N$17=N25,TRUE,FALSE) -> FALSE
J26: 감전 | K26: =IF(J26=$J$17,TRUE,FALSE) -> FALSE | L26: 설비 | M26: =IF($L$17=L26,TRUE,FALSE) -> FALSE | N26: 기타 | O26: =IF(COUNTIF(N17,"*기타*"),TRUE,FALSE) -> TRUE
D27: 불안전한 행동 : | J27: 요통 | K27: =IF(J27=$J$17,TRUE,FALSE) -> FALSE | L27: 정리정돈 | M27: =IF($L$17=L27,TRUE,FALSE) -> FALSE
J28: 화상/동상 | K28: =IF(J28=$J$17,TRUE,FALSE) -> FALSE | L28: 자연재해 | M28: =IF($L$17=L28,TRUE,FALSE) -> FALSE
J29: 기타 | K29: =IF(J29=$J$17,TRUE,FALSE) -> FALSE | L29: 기타 | M29: =IF($L$17=L29,TRUE,FALSE) -> FALSE
J30: 설비 사고 | K30: =IF(J30=$J$17,TRUE,FALSE) -> FALSE | L30: 계단 | M30: =IF($L$17=L30,TRUE,FALSE) -> FALSE
J31: 유해물질 접촉 | K31: =IF(J31=$J$17,TRUE,FALSE) -> FALSE | L31: 낙석 | M31: =IF($L$17=L31,TRUE,FALSE) -> FALSE
J32: 화재/ 폭발 | K32: =IF(J32=$J$17,TRUE,FALSE) -> FALSE | L32: 폭설/ 결빙 | M32: =IF($L$17=L32,TRUE,FALSE) -> FALSE
J33: 익사 | K33: =IF(J33=$J$17,TRUE,FALSE) -> FALSE | L33: 도구 및 장비 | M33: =IF($L$17=L33,TRUE,FALSE) -> FALSE
J34: 절단/ 찰과상 | K34: =IF(J34=$J$17,TRUE,FALSE) -> FALSE | L34: 동물/ 뱀/ 벌 | M34: =IF($L$17=L34,TRUE,FALSE) -> FALSE
A35: 사고 방지를 위해 | B35: ※ 보고자가 조치한 사항이 있는경우에 기록 해 주시기 바랍니다. | J35: 분류 불능 | K35: =IF(J35=$J$17,TRUE,FALSE) -> FALSE | L35: 제3자 | M35: =IF($L$17=L35,TRUE,FALSE) -> FALSE
A36: 저는 이렇게 | B36: =_xlfn.LET( _xlpm.RESULT, _xlfn.XLOOKUP(B7,near_miss_excel_view!C:C,near_miss_excel_view!N:N,"없음",0,1), _xlpm.ANOTHER, _xlfn.XLOOKUP(B7,near_miss_excel_view!C:C,near_miss_excel_view!M:M,"없음",0,1), IF(_xlpm.RESULT="",_xlpm.ANOTHER,_xlpm.RESULT)) -> 서두르지 않고 작업을 하겠습니다 | J36: 차량사고 | K36: =IF(J36=$J$17,TRUE,FALSE) -> FALSE | L36: 조명/ 환경 | M36: =IF($L$17=L36,TRUE,FALSE) -> FALSE
A37: 조치하였습니다
A39: ▶ 제안자는 위의 사항들만 작성하시어 관련팀에 제출하여 주시기 바랍니다.
A40: 다음과 같은 | B40: ※ 아차사고확인자(접수팀)에 의해 수립된 계획
A41: 조치를 취해
A42: 주시기 바랍니다
A44: 제안사항 확인 | B44: 접수팀 | C44: (인) | F44: 안전관리팀으로 제출 후 개선계획을 기록/보관하여 주시기 바랍니다.
A45: ▶ 접수팀에서는 접수 즉시 안전보건팀으로 제출하여 주시기 바랍니다.
A46: 접수 확인 | B46: 안전관리팀 | C46: (인)
A47: ▶ 접수팀에서는 팀장 확인 후 자체 보관하여 주시기 바랍니다.
...

Sheet 보고서(4-02)
B1: (■ 아차사고 , □ 응급처치 ) 보고서
A3: ■ 아차사고 보고서를 이용하여, 상황이 다소 달랐다면 인명피해로 이어질수 있었던 사고를 보고해 주시기 바랍니다
A4: ■ 여러분의 협조가 당사의 인적, 물적 피해를 줄일 수 있으며 예방하는 도움이 됩니다
H5: ="작성일 : "&TEXT(_xlfn.XLOOKUP(B7,near_miss_excel_view!C:C,near_miss_excel_view!D:D,"없음",0,1),"YY-MM-DD") -> 작성일 : 26-04-02
A6: 소 속 | B6: 현대기전 | D6: 성 명 | E6: =_xlfn.XLOOKUP(B7,near_miss_excel_view!C:C,near_miss_excel_view!B:B,"없음",0,1) -> 장진혁 | G6: 사 번
A7: 아차사고명 | B7: 4호 inlet 이젝터 청소 작업 중 이젝터 나사가 바닥에 떨어짐, 나사를 찾으려다 바닥에 넘어질뻔함
A9: 아차사고 | B9: =" 1. 발생 일시 : "&TEXT(_xlfn.XLOOKUP(B7,near_miss_excel_view!C:C,near_miss_excel_view!D:D,"없음",0,1),"YYYY년 MM월 DD일 hh시 mm분")&" 경" -> 1. 발생 일시 : 2026년 04월 02일 09시 50분 경
A10: 경험(목격) | B10: =" 2. 발생 장소 : "&_xlfn.XLOOKUP(B7,near_miss_excel_view!C:C,near_miss_excel_view!E:E,"없음",0,1) -> 2. 발생 장소 : 4호 kiln inlet
A11: 내용 및 | B11: {=" 3. 내용 / 원인 : "&_xlfn.XLOOKUP(B7,near_miss_excel_view!C:C,CHAR(10)&"내용: "&near_miss_excel_view!F:F&CHAR(10)&"원인: "&near_miss_excel_view!G:G,"없음",0,1)} -> 3. 내용 / 원인 : 내용: 4k inlet 이젝터 청소를 하다 바닥에 나사가 떨어짐, 나사를 찾으려 움직이다 바닥에 넘어질 뻔함 원인: 바닥 근처에 공구가방이 있었는데 나사를 찾으려다 확인하지 못함
A12: 원인 입니다
J16: 사고유형 | L16: 불안전한상태 | N16: 불안전한행동 | P16: 부주의 행동 | R16: 부주의 상태
A17: 다음 해당하는 사항에 체크하세요. | J17: =_xlfn.XLOOKUP(B7,near_miss_excel_view!$C:$C,near_miss_excel_view!H:H,"없음",0,1) -> 전도 | L17: =_xlfn.XLOOKUP(B7,near_miss_excel_view!$C:$C,near_miss_excel_view!I:I,"없음",0,1) -> 정리정돈 | N17: =_xlfn.XLOOKUP(B7,near_miss_excel_view!$C:$C,near_miss_excel_view!J:J,"없음",0,1) -> 불안전한 자세 | P17: =_xlfn.XLOOKUP(B7,near_miss_excel_view!$C:$C,near_miss_excel_view!K:K,"없음",0,1) -> 위험경로에 위치함 | R17: =_xlfn.XLOOKUP(B7,near_miss_excel_view!$C:$C,near_miss_excel_view!L:L,"없음",0,1) -> 서두름
A18: 사고 유형 | D18: 불안전한 상태 :
J19: 추락 | K19: =IF(J19=$J$17,TRUE,FALSE) -> FALSE | L19: 통로 | M19: =IF($L$17=L19,TRUE,FALSE) -> FALSE | N19: 규정위반 | O19: =IF($N$17=N19,TRUE,FALSE) -> FALSE | P19: 위험경로에 위치함 | Q19: =IF($P$17=P19,TRUE,FALSE) -> TRUE | R19: 서두름 | S19: =IF($R$17=R19,TRUE,FALSE) -> TRUE
J20: 전도 | K20: =IF(J20=$J$17,TRUE,FALSE) -> TRUE | L20: 돌출부 | M20: =IF($L$17=L20,TRUE,FALSE) -> FALSE | N20: 도구의 잘못 사용 | O20: =IF($N$17=N20,TRUE,FALSE) -> FALSE | P20: 몸의 균형이 불안정해짐 | Q20: =IF($P$17=P20,TRUE,FALSE) -> FALSE | R20: 피로 | S20: =IF($R$17=R20,TRUE,FALSE) -> FALSE
J21: 충돌 | K21: =IF(J21=$J$17,TRUE,FALSE) -> FALSE | L21: 안전난간 | M21: =IF($L$17=L21,TRUE,FALSE) -> FALSE | N21: 무거운 짐 취급 | O21: =IF($N$17=N21,TRUE,FALSE) -> FALSE | P21: 위험을 보지 않음 | Q21: =IF($P$17=P21,TRUE,FALSE) -> FALSE | R21: 스트레스 | S21: =IF($R$17=R21,TRUE,FALSE) -> FALSE
J22: 낙하 | K22: =IF(J22=$J$17,TRUE,FALSE) -> FALSE | L22: 작업발판 | M22: =IF($L$17=L22,TRUE,FALSE) -> FALSE | N22: 보호구 | O22: =IF($N$17=N22,TRUE,FALSE) -> FALSE | P22: 위험을 생각하지 않음 | Q22: =IF($P$17=P22,TRUE,FALSE) -> FALSE | R22: 자만심 | S22: =IF($R$17=R22,TRUE,FALSE) -> FALSE
J23: 비래 | K23: =IF(J23=$J$17,TRUE,FALSE) -> FALSE | L23: 개구부 | M23: =IF($L$17=L23,TRUE,FALSE) -> FALSE | N23: 불안전한 자세 | O23: =IF($N$17=N23,TRUE,FALSE) -> TRUE
J24: 붕괴 | K24: =IF(J24=$J$17,TRUE,FALSE) -> FALSE | L24: 전기 | M24: =IF($L$17=L24,TRUE,FALSE) -> FALSE | N24: 소통 미비 | O24: =IF($N$17=N24,TRUE,FALSE) -> FALSE
J25: 협착 | K25: =IF(J25=$J$17,TRUE,FALSE) -> FALSE | L25: 운전장비 | M25: =IF($L$17=L25,TRUE,FALSE) -> FALSE | N25: 평소 습관 | O25: =IF($N$17=N25,TRUE,FALSE) -> FALSE
J26: 감전 | K26: =IF(J26=$J$17,TRUE,FALSE) -> FALSE | L26: 설비 | M26: =IF($L$17=L26,TRUE,FALSE) -> FALSE | N26: 기타 | O26: =IF(COUNTIF(N17,"*기타*"),TRUE,FALSE) -> FALSE
D27: 불안전한 행동 : | J27: 요통 | K27: =IF(J27=$J$17,TRUE,FALSE) -> FALSE | L27: 정리정돈 | M27: =IF($L$17=L27,TRUE,FALSE) -> TRUE
J28: 화상/동상 | K28: =IF(J28=$J$17,TRUE,FALSE) -> FALSE | L28: 자연재해 | M28: =IF($L$17=L28,TRUE,FALSE) -> FALSE
J29: 기타 | K29: =IF(J29=$J$17,TRUE,FALSE) -> FALSE | L29: 기타 | M29: =IF($L$17=L29,TRUE,FALSE) -> FALSE
J30: 설비 사고 | K30: =IF(J30=$J$17,TRUE,FALSE) -> FALSE | L30: 계단 | M30: =IF($L$17=L30,TRUE,FALSE) -> FALSE
J31: 유해물질 접촉 | K31: =IF(J31=$J$17,TRUE,FALSE) -> FALSE | L31: 낙석 | M31: =IF($L$17=L31,TRUE,FALSE) -> FALSE
J32: 화재/ 폭발 | K32: =IF(J32=$J$17,TRUE,FALSE) -> FALSE | L32: 폭설/ 결빙 | M32: =IF($L$17=L32,TRUE,FALSE) -> FALSE
J33: 익사 | K33: =IF(J33=$J$17,TRUE,FALSE) -> FALSE | L33: 도구 및 장비 | M33: =IF($L$17=L33,TRUE,FALSE) -> FALSE
J34: 절단/ 찰과상 | K34: =IF(J34=$J$17,TRUE,FALSE) -> FALSE | L34: 동물/ 뱀/ 벌 | M34: =IF($L$17=L34,TRUE,FALSE) -> FALSE
A35: 사고 방지를 위해 | B35: ※ 보고자가 조치한 사항이 있는경우에 기록 해 주시기 바랍니다. | J35: 분류 불능 | K35: =IF(J35=$J$17,TRUE,FALSE) -> FALSE | L35: 제3자 | M35: =IF($L$17=L35,TRUE,FALSE) -> FALSE
A36: 저는 이렇게 | B36: =_xlfn.LET( _xlpm.RESULT, _xlfn.XLOOKUP(B7,near_miss_excel_view!C:C,near_miss_excel_view!N:N,"없음",0,1), _xlpm.ANOTHER, _xlfn.XLOOKUP(B7,near_miss_excel_view!C:C,near_miss_excel_view!M:M,"없음",0,1), IF(_xlpm.RESULT="",_xlpm.ANOTHER,_xlpm.RESULT)) -> 주변 동선 확인 후 작업 | J36: 차량사고 | K36: =IF(J36=$J$17,TRUE,FALSE) -> FALSE | L36: 조명/ 환경 | M36: =IF($L$17=L36,TRUE,FALSE) -> FALSE
A37: 조치하였습니다
A39: ▶ 제안자는 위의 사항들만 작성하시어 관련팀에 제출하여 주시기 바랍니다.
A40: 다음과 같은 | B40: ※ 아차사고확인자(접수팀)에 의해 수립된 계획
A41: 조치를 취해
A42: 주시기 바랍니다
A44: 제안사항 확인 | B44: 접수팀 | C44: (인) | F44: 안전관리팀으로 제출 후 개선계획을 기록/보관하여 주시기 바랍니다.
A45: ▶ 접수팀에서는 접수 즉시 안전보건팀으로 제출하여 주시기 바랍니다.
A46: 접수 확인 | B46: 안전관리팀 | C46: (인)
A47: ▶ 접수팀에서는 팀장 확인 후 자체 보관하여 주시기 바랍니다.
...

Sheet 보고서(4-03)
B1: (■ 아차사고 , □ 응급처치 ) 보고서
A3: ■ 아차사고 보고서를 이용하여, 상황이 다소 달랐다면 인명피해로 이어질수 있었던 사고를 보고해 주시기 바랍니다
A4: ■ 여러분의 협조가 당사의 인적, 물적 피해를 줄일 수 있으며 예방하는 도움이 됩니다
H5: ="작성일 : "&TEXT(_xlfn.XLOOKUP(B7,near_miss_excel_view!C:C,near_miss_excel_view!D:D,"없음",0,1),"YY-MM-DD") -> 작성일 : 26-04-03
A6: 소 속 | B6: 현대기전 | D6: 성 명 | E6: =_xlfn.XLOOKUP(B7,near_miss_excel_view!C:C,near_miss_excel_view!B:B,"없음",0,1) -> 김도담 | G6: 사 번
A7: 아차사고명 | B7: 공구 사용하다 칠과상
A9: 아차사고 | B9: =" 1. 발생 일시 : "&TEXT(_xlfn.XLOOKUP(B7,near_miss_excel_view!C:C,near_miss_excel_view!D:D,"없음",0,1),"YYYY년 MM월 DD일 hh시 mm분")&" 경" -> 1. 발생 일시 : 2026년 04월 03일 09시 06분 경
A10: 경험(목격) | B10: =" 2. 발생 장소 : "&_xlfn.XLOOKUP(B7,near_miss_excel_view!C:C,near_miss_excel_view!E:E,"없음",0,1) -> 2. 발생 장소 : 4k kiln inlet
A11: 내용 및 | B11: {=" 3. 내용 / 원인 : "&_xlfn.XLOOKUP(B7,near_miss_excel_view!C:C,CHAR(10)&"내용: "&near_miss_excel_view!F:F&CHAR(10)&"원인: "&near_miss_excel_view!G:G,"없음",0,1)} -> 3. 내용 / 원인 : 내용: 파이브렌치를 사용하다 헛돌아 넘어짐 원인: 공구를 체결 시 손잡이와 파이프가 수직상태에 놓이지 않은 상태로, 몸의 위치가 손잡이 중심선에서 많이 벗어난 상태였음
A12: 원인 입니다
J16: 사고유형 | L16: 불안전한상태 | N16: 불안전한행동 | P16: 부주의 행동 | R16: 부주의 상태
A17: 다음 해당하는 사항에 체크하세요. | J17: =_xlfn.XLOOKUP(B7,near_miss_excel_view!$C:$C,near_miss_excel_view!H:H,"없음",0,1) -> 절단/찰과상 | L17: =_xlfn.XLOOKUP(B7,near_miss_excel_view!$C:$C,near_miss_excel_view!I:I,"없음",0,1) -> 도구 및 장비 | N17: =_xlfn.XLOOKUP(B7,near_miss_excel_view!$C:$C,near_miss_excel_view!J:J,"없음",0,1) -> 불안전한 자세 | P17: =_xlfn.XLOOKUP(B7,near_miss_excel_view!$C:$C,near_miss_excel_view!K:K,"없음",0,1) -> 몸의 균형이 불안정해짐 | R17: =_xlfn.XLOOKUP(B7,near_miss_excel_view!$C:$C,near_miss_excel_view!L:L,"없음",0,1) -> 서두름
A18: 사고 유형 | D18: 불안전한 상태 :
J19: 추락 | K19: =IF(J19=$J$17,TRUE,FALSE) -> FALSE | L19: 통로 | M19: =IF($L$17=L19,TRUE,FALSE) -> FALSE | N19: 규정위반 | O19: =IF($N$17=N19,TRUE,FALSE) -> FALSE | P19: 위험경로에 위치함 | Q19: =IF($P$17=P19,TRUE,FALSE) -> FALSE | R19: 서두름 | S19: =IF($R$17=R19,TRUE,FALSE) -> TRUE
J20: 전도 | K20: =IF(J20=$J$17,TRUE,FALSE) -> FALSE | L20: 돌출부 | M20: =IF($L$17=L20,TRUE,FALSE) -> FALSE | N20: 도구의 잘못 사용 | O20: =IF($N$17=N20,TRUE,FALSE) -> FALSE | P20: 몸의 균형이 불안정해짐 | Q20: =IF($P$17=P20,TRUE,FALSE) -> TRUE | R20: 피로 | S20: =IF($R$17=R20,TRUE,FALSE) -> FALSE
J21: 충돌 | K21: =IF(J21=$J$17,TRUE,FALSE) -> FALSE | L21: 안전난간 | M21: =IF($L$17=L21,TRUE,FALSE) -> FALSE | N21: 무거운 짐 취급 | O21: =IF($N$17=N21,TRUE,FALSE) -> FALSE | P21: 위험을 보지 않음 | Q21: =IF($P$17=P21,TRUE,FALSE) -> FALSE | R21: 스트레스 | S21: =IF($R$17=R21,TRUE,FALSE) -> FALSE
J22: 낙하 | K22: =IF(J22=$J$17,TRUE,FALSE) -> FALSE | L22: 작업발판 | M22: =IF($L$17=L22,TRUE,FALSE) -> FALSE | N22: 보호구 | O22: =IF($N$17=N22,TRUE,FALSE) -> FALSE | P22: 위험을 생각하지 않음 | Q22: =IF($P$17=P22,TRUE,FALSE) -> FALSE | R22: 자만심 | S22: =IF($R$17=R22,TRUE,FALSE) -> FALSE
J23: 비래 | K23: =IF(J23=$J$17,TRUE,FALSE) -> FALSE | L23: 개구부 | M23: =IF($L$17=L23,TRUE,FALSE) -> FALSE | N23: 불안전한 자세 | O23: =IF($N$17=N23,TRUE,FALSE) -> TRUE
J24: 붕괴 | K24: =IF(J24=$J$17,TRUE,FALSE) -> FALSE | L24: 전기 | M24: =IF($L$17=L24,TRUE,FALSE) -> FALSE | N24: 소통 미비 | O24: =IF($N$17=N24,TRUE,FALSE) -> FALSE
J25: 협착 | K25: =IF(J25=$J$17,TRUE,FALSE) -> FALSE | L25: 운전장비 | M25: =IF($L$17=L25,TRUE,FALSE) -> FALSE | N25: 평소 습관 | O25: =IF($N$17=N25,TRUE,FALSE) -> FALSE
J26: 감전 | K26: =IF(J26=$J$17,TRUE,FALSE) -> FALSE | L26: 설비 | M26: =IF($L$17=L26,TRUE,FALSE) -> FALSE | N26: 기타 | O26: =IF(COUNTIF(N17,"*기타*"),TRUE,FALSE) -> FALSE
D27: 불안전한 행동 : | J27: 요통 | K27: =IF(J27=$J$17,TRUE,FALSE) -> FALSE | L27: 정리정돈 | M27: =IF($L$17=L27,TRUE,FALSE) -> FALSE
J28: 화상/동상 | K28: =IF(J28=$J$17,TRUE,FALSE) -> FALSE | L28: 자연재해 | M28: =IF($L$17=L28,TRUE,FALSE) -> FALSE
J29: 기타 | K29: =IF(J29=$J$17,TRUE,FALSE) -> FALSE | L29: 기타 | M29: =IF($L$17=L29,TRUE,FALSE) -> FALSE
J30: 설비 사고 | K30: =IF(J30=$J$17,TRUE,FALSE) -> FALSE | L30: 계단 | M30: =IF($L$17=L30,TRUE,FALSE) -> FALSE
J31: 유해물질 접촉 | K31: =IF(J31=$J$17,TRUE,FALSE) -> FALSE | L31: 낙석 | M31: =IF($L$17=L31,TRUE,FALSE) -> FALSE
J32: 화재/ 폭발 | K32: =IF(J32=$J$17,TRUE,FALSE) -> FALSE | L32: 폭설/ 결빙 | M32: =IF($L$17=L32,TRUE,FALSE) -> FALSE
J33: 익사 | K33: =IF(J33=$J$17,TRUE,FALSE) -> FALSE | L33: 도구 및 장비 | M33: =IF($L$17=L33,TRUE,FALSE) -> TRUE
J34: 절단/찰과상 | K34: =IF(J34=$J$17,TRUE,FALSE) -> TRUE | L34: 동물/ 뱀/ 벌 | M34: =IF($L$17=L34,TRUE,FALSE) -> FALSE
A35: 사고 방지를 위해 | B35: ※ 보고자가 조치한 사항이 있는경우에 기록 해 주시기 바랍니다. | J35: 분류 불능 | K35: =IF(J35=$J$17,TRUE,FALSE) -> FALSE | L35: 제3자 | M35: =IF($L$17=L35,TRUE,FALSE) -> FALSE
A36: 저는 이렇게 | B36: =_xlfn.LET( _xlpm.RESULT, _xlfn.XLOOKUP(B7,near_miss_excel_view!C:C,near_miss_excel_view!N:N,"없음",0,1), _xlpm.ANOTHER, _xlfn.XLOOKUP(B7,near_miss_excel_view!C:C,near_miss_excel_view!M:M,"없음",0,1), IF(_xlpm.RESULT="",_xlpm.ANOTHER,_xlpm.RESULT)) -> 급하게 작업하기보단 공구가 체결된거 확인후_x000D_ 안전하게 작업 | J36: 차량사고 | K36: =IF(J36=$J$17,TRUE,FALSE) -> FALSE | L36: 조명/ 환경 | M36: =IF($L$17=L36,TRUE,FALSE) -> FALSE
A37: 조치하였습니다
A39: ▶ 제안자는 위의 사항들만 작성하시어 관련팀에 제출하여 주시기 바랍니다.
A40: 다음과 같은 | B40: ※ 아차사고확인자(접수팀)에 의해 수립된 계획
A41: 조치를 취해
A42: 주시기 바랍니다
A44: 제안사항 확인 | B44: 접수팀 | C44: (인) | F44: 안전관리팀으로 제출 후 개선계획을 기록/보관하여 주시기 바랍니다.
A45: ▶ 접수팀에서는 접수 즉시 안전보건팀으로 제출하여 주시기 바랍니다.
A46: 접수 확인 | B46: 안전관리팀 | C46: (인)
A47: ▶ 접수팀에서는 팀장 확인 후 자체 보관하여 주시기 바랍니다.
...

Sheet 보고서(4-13) (2)
B1: (■ 아차사고 , □ 응급처치 ) 보고서
A3: ■ 아차사고 보고서를 이용하여, 상황이 다소 달랐다면 인명피해로 이어질수 있었던 사고를 보고해 주시기 바랍니다
A4: ■ 여러분의 협조가 당사의 인적, 물적 피해를 줄일 수 있으며 예방하는 도움이 됩니다
H5: ="작성일 : "&TEXT(_xlfn.XLOOKUP(B7,near_miss_excel_view!C:C,near_miss_excel_view!D:D,"없음",0,1),"YY-MM-DD") -> 작성일 : 26-04-13
A6: 소 속 | B6: 현대기전 | D6: 성 명 | E6: =_xlfn.XLOOKUP(B7,near_miss_excel_view!C:C,near_miss_excel_view!B:B,"없음",0,1) -> 이정민 | G6: 사 번
A7: 아차사고명 | B7: 판넬 이송 중 머리 부딪힘
A9: 아차사고 | B9: =" 1. 발생 일시 : "&TEXT(_xlfn.XLOOKUP(B7,near_miss_excel_view!C:C,near_miss_excel_view!D:D,"없음",0,1),"YYYY년 MM월 DD일 hh시 mm분")&" 경" -> 1. 발생 일시 : 2026년 04월 13일 08시 10분 경
A10: 경험(목격) | B10: =" 2. 발생 장소 : "&_xlfn.XLOOKUP(B7,near_miss_excel_view!C:C,near_miss_excel_view!E:E,"없음",0,1) -> 2. 발생 장소 : 현대기전 사무실
A11: 내용 및 | B11: {=" 3. 내용 / 원인 : "&_xlfn.XLOOKUP(B7,near_miss_excel_view!C:C,CHAR(10)&"내용: "&near_miss_excel_view!F:F&CHAR(10)&"원인: "&near_miss_excel_view!G:G,"없음",0,1)} -> 3. 내용 / 원인 : 내용: 판넬을 사무실 밖으로 빼기 위해 구르마로 이동 중 사무실 문 앞 턱에서 판넬이 기울어지며 넘어감 그 후 넘어가는 쪽에 있던 인원이 머리를 부딪힘. 원인: 서두르다가 이동경로의 장애물을 생각하지 못함.
A12: 원인 입니다
J16: 사고유형 | L16: 불안전한상태 | N16: 불안전한행동 | P16: 부주의 행동 | R16: 부주의 상태
A17: 다음 해당하는 사항에 체크하세요. | J17: =_xlfn.XLOOKUP(B7,near_miss_excel_view!$C:$C,near_miss_excel_view!H:H,"없음",0,1) -> 전도 | L17: =_xlfn.XLOOKUP(B7,near_miss_excel_view!$C:$C,near_miss_excel_view!I:I,"없음",0,1) -> 통로 | N17: =_xlfn.XLOOKUP(B7,near_miss_excel_view!$C:$C,near_miss_excel_view!J:J,"없음",0,1) -> 불안전한 자세 | P17: =_xlfn.XLOOKUP(B7,near_miss_excel_view!$C:$C,near_miss_excel_view!K:K,"없음",0,1) -> 위험경로에 위치함 | R17: =_xlfn.XLOOKUP(B7,near_miss_excel_view!$C:$C,near_miss_excel_view!L:L,"없음",0,1) -> 자만심
A18: 사고 유형 | D18: 불안전한 상태 :
J19: 추락 | K19: =IF(J19=$J$17,TRUE,FALSE) -> FALSE | L19: 통로 | M19: =IF($L$17=L19,TRUE,FALSE) -> TRUE | N19: 규정위반 | O19: =IF($N$17=N19,TRUE,FALSE) -> FALSE | P19: 위험경로에 위치함 | Q19: =IF($P$17=P19,TRUE,FALSE) -> TRUE | R19: 서두름 | S19: =IF($R$17=R19,TRUE,FALSE) -> FALSE
J20: 전도 | K20: =IF(J20=$J$17,TRUE,FALSE) -> TRUE | L20: 돌출부 | M20: =IF($L$17=L20,TRUE,FALSE) -> FALSE | N20: 도구의 잘못 사용 | O20: =IF($N$17=N20,TRUE,FALSE) -> FALSE | P20: 몸의 균형이 불안정해짐 | Q20: =IF($P$17=P20,TRUE,FALSE) -> FALSE | R20: 피로 | S20: =IF($R$17=R20,TRUE,FALSE) -> FALSE
J21: 충돌 | K21: =IF(J21=$J$17,TRUE,FALSE) -> FALSE | L21: 안전난간 | M21: =IF($L$17=L21,TRUE,FALSE) -> FALSE | N21: 무거운 짐 취급 | O21: =IF($N$17=N21,TRUE,FALSE) -> FALSE | P21: 위험을 보지 않음 | Q21: =IF($P$17=P21,TRUE,FALSE) -> FALSE | R21: 스트레스 | S21: =IF($R$17=R21,TRUE,FALSE) -> FALSE
J22: 낙하 | K22: =IF(J22=$J$17,TRUE,FALSE) -> FALSE | L22: 작업발판 | M22: =IF($L$17=L22,TRUE,FALSE) -> FALSE | N22: 보호구 | O22: =IF($N$17=N22,TRUE,FALSE) -> FALSE | P22: 위험을 생각하지 않음 | Q22: =IF($P$17=P22,TRUE,FALSE) -> FALSE | R22: 자만심 | S22: =IF($R$17=R22,TRUE,FALSE) -> TRUE
J23: 비래 | K23: =IF(J23=$J$17,TRUE,FALSE) -> FALSE | L23: 개구부 | M23: =IF($L$17=L23,TRUE,FALSE) -> FALSE | N23: 불안전한 자세 | O23: =IF($N$17=N23,TRUE,FALSE) -> TRUE
J24: 붕괴 | K24: =IF(J24=$J$17,TRUE,FALSE) -> FALSE | L24: 전기 | M24: =IF($L$17=L24,TRUE,FALSE) -> FALSE | N24: 소통 미비 | O24: =IF($N$17=N24,TRUE,FALSE) -> FALSE
J25: 협착 | K25: =IF(J25=$J$17,TRUE,FALSE) -> FALSE | L25: 운전장비 | M25: =IF($L$17=L25,TRUE,FALSE) -> FALSE | N25: 평소 습관 | O25: =IF($N$17=N25,TRUE,FALSE) -> FALSE
J26: 감전 | K26: =IF(J26=$J$17,TRUE,FALSE) -> FALSE | L26: 설비 | M26: =IF($L$17=L26,TRUE,FALSE) -> FALSE | N26: 기타 | O26: =IF(COUNTIF(N17,"*기타*"),TRUE,FALSE) -> FALSE
D27: 불안전한 행동 : | J27: 요통 | K27: =IF(J27=$J$17,TRUE,FALSE) -> FALSE | L27: 정리정돈 | M27: =IF($L$17=L27,TRUE,FALSE) -> FALSE
J28: 화상/동상 | K28: =IF(J28=$J$17,TRUE,FALSE) -> FALSE | L28: 자연재해 | M28: =IF($L$17=L28,TRUE,FALSE) -> FALSE
J29: 기타 | K29: =IF(J29=$J$17,TRUE,FALSE) -> FALSE | L29: 기타 | M29: =IF($L$17=L29,TRUE,FALSE) -> FALSE
J30: 설비 사고 | K30: =IF(J30=$J$17,TRUE,FALSE) -> FALSE | L30: 계단 | M30: =IF($L$17=L30,TRUE,FALSE) -> FALSE
J31: 유해물질 접촉 | K31: =IF(J31=$J$17,TRUE,FALSE) -> FALSE | L31: 낙석 | M31: =IF($L$17=L31,TRUE,FALSE) -> FALSE
J32: 화재/ 폭발 | K32: =IF(J32=$J$17,TRUE,FALSE) -> FALSE | L32: 폭설/ 결빙 | M32: =IF($L$17=L32,TRUE,FALSE) -> FALSE
J33: 익사 | K33: =IF(J33=$J$17,TRUE,FALSE) -> FALSE | L33: 도구 및 장비 | M33: =IF($L$17=L33,TRUE,FALSE) -> FALSE
J34: 절단/ 찰과상 | K34: =IF(J34=$J$17,TRUE,FALSE) -> FALSE | L34: 동물/ 뱀/ 벌 | M34: =IF($L$17=L34,TRUE,FALSE) -> FALSE
A35: 사고 방지를 위해 | B35: ※ 보고자가 조치한 사항이 있는경우에 기록 해 주시기 바랍니다. | J35: 분류 불능 | K35: =IF(J35=$J$17,TRUE,FALSE) -> FALSE | L35: 제3자 | M35: =IF($L$17=L35,TRUE,FALSE) -> FALSE
A36: 저는 이렇게 | B36: =_xlfn.LET( _xlpm.RESULT, _xlfn.XLOOKUP(B7,near_miss_excel_view!C:C,near_miss_excel_view!N:N,"없음",0,1), _xlpm.ANOTHER, _xlfn.XLOOKUP(B7,near_miss_excel_view!C:C,near_miss_excel_view!M:M,"없음",0,1), IF(_xlpm.RESULT="",_xlpm.ANOTHER,_xlpm.RESULT)) -> 사용했던 구르마보다 큰 규격의 구르마를 사용하고 판넬을 세워서 이동하지 않고 눕혀서 2명 이상의 인원이 함께 작업을 하였습니다. | J36: 차량사고 | K36: =IF(J36=$J$17,TRUE,FALSE) -> FALSE | L36: 조명/ 환경 | M36: =IF($L$17=L36,TRUE,FALSE) -> FALSE
A37: 조치하였습니다
A39: ▶ 제안자는 위의 사항들만 작성하시어 관련팀에 제출하여 주시기 바랍니다.
A40: 다음과 같은 | B40: ※ 아차사고확인자(접수팀)에 의해 수립된 계획
A41: 조치를 취해
A42: 주시기 바랍니다
A44: 제안사항 확인 | B44: 접수팀 | C44: (인) | F44: 안전관리팀으로 제출 후 개선계획을 기록/보관하여 주시기 바랍니다.
A45: ▶ 접수팀에서는 접수 즉시 안전보건팀으로 제출하여 주시기 바랍니다.
A46: 접수 확인 | B46: 안전관리팀 | C46: (인)
A47: ▶ 접수팀에서는 팀장 확인 후 자체 보관하여 주시기 바랍니다.
...

Sheet 보고서(4-13)
B1: (■ 아차사고 , □ 응급처치 ) 보고서
A3: ■ 아차사고 보고서를 이용하여, 상황이 다소 달랐다면 인명피해로 이어질수 있었던 사고를 보고해 주시기 바랍니다
A4: ■ 여러분의 협조가 당사의 인적, 물적 피해를 줄일 수 있으며 예방하는 도움이 됩니다
H5: ="작성일 : "&TEXT(_xlfn.XLOOKUP(B7,near_miss_excel_view!C:C,near_miss_excel_view!D:D,"없음",0,1),"YY-MM-DD") -> 작성일 : 26-04-13
A6: 소 속 | B6: 현대기전 | D6: 성 명 | E6: =_xlfn.XLOOKUP(B7,near_miss_excel_view!C:C,near_miss_excel_view!B:B,"없음",0,1) -> 이정민 | G6: 사 번
A7: 아차사고명 | B7: 광산현대화 BC2 벨트에서 이동식 비계를 옮기던 중 미끄러짐
A9: 아차사고 | B9: =" 1. 발생 일시 : "&TEXT(_xlfn.XLOOKUP(B7,near_miss_excel_view!C:C,near_miss_excel_view!D:D,"없음",0,1),"YYYY년 MM월 DD일 hh시 mm분")&" 경" -> 1. 발생 일시 : 2026년 04월 13일 10시 20분 경
A10: 경험(목격) | B10: =" 2. 발생 장소 : "&_xlfn.XLOOKUP(B7,near_miss_excel_view!C:C,near_miss_excel_view!E:E,"없음",0,1) -> 2. 발생 장소 : 광산 320갱 BC2벨트
A11: 내용 및 | B11: {=" 3. 내용 / 원인 : "&_xlfn.XLOOKUP(B7,near_miss_excel_view!C:C,CHAR(10)&"내용: "&near_miss_excel_view!F:F&CHAR(10)&"원인: "&near_miss_excel_view!G:G,"없음",0,1)} -> 3. 내용 / 원인 : 내용: BC2벨트 구조물 위에 안착해놨던 이동식 비계를 CRUSHER방향으로 테스트 겸 밀던 중 벨트위에 고여있던 물들과 부석들이 발에 걸리며 미끄러질뻔함. 원인: 이동하기 전에 이동경로에 장애물이 있는지 사전 조사실시 미흡.
A12: 원인 입니다
J16: 사고유형 | L16: 불안전한상태 | N16: 불안전한행동 | P16: 부주의 행동 | R16: 부주의 상태
A17: 다음 해당하는 사항에 체크하세요. | J17: =_xlfn.XLOOKUP(B7,near_miss_excel_view!$C:$C,near_miss_excel_view!H:H,"없음",0,1) -> 전도 | L17: =_xlfn.XLOOKUP(B7,near_miss_excel_view!$C:$C,near_miss_excel_view!I:I,"없음",0,1) -> 통로 | N17: =_xlfn.XLOOKUP(B7,near_miss_excel_view!$C:$C,near_miss_excel_view!J:J,"없음",0,1) -> 기타: 무거운 짐 취급 | P17: =_xlfn.XLOOKUP(B7,near_miss_excel_view!$C:$C,near_miss_excel_view!K:K,"없음",0,1) -> 몸의 균형이 불안정해짐 | R17: =_xlfn.XLOOKUP(B7,near_miss_excel_view!$C:$C,near_miss_excel_view!L:L,"없음",0,1) -> 서두름
A18: 사고 유형 | D18: 불안전한 상태 :
J19: 추락 | K19: =IF(J19=$J$17,TRUE,FALSE) -> FALSE | L19: 통로 | M19: =IF($L$17=L19,TRUE,FALSE) -> TRUE | N19: 규정위반 | O19: =IF($N$17=N19,TRUE,FALSE) -> FALSE | P19: 위험경로에 위치함 | Q19: =IF($P$17=P19,TRUE,FALSE) -> FALSE | R19: 서두름 | S19: =IF($R$17=R19,TRUE,FALSE) -> TRUE
J20: 전도 | K20: =IF(J20=$J$17,TRUE,FALSE) -> TRUE | L20: 돌출부 | M20: =IF($L$17=L20,TRUE,FALSE) -> FALSE | N20: 도구의 잘못 사용 | O20: =IF($N$17=N20,TRUE,FALSE) -> FALSE | P20: 몸의 균형이 불안정해짐 | Q20: =IF($P$17=P20,TRUE,FALSE) -> TRUE | R20: 피로 | S20: =IF($R$17=R20,TRUE,FALSE) -> FALSE
J21: 충돌 | K21: =IF(J21=$J$17,TRUE,FALSE) -> FALSE | L21: 안전난간 | M21: =IF($L$17=L21,TRUE,FALSE) -> FALSE | N21: 무거운 짐 취급 | O21: =IF($N$17=N21,TRUE,FALSE) -> FALSE | P21: 위험을 보지 않음 | Q21: =IF($P$17=P21,TRUE,FALSE) -> FALSE | R21: 스트레스 | S21: =IF($R$17=R21,TRUE,FALSE) -> FALSE
J22: 낙하 | K22: =IF(J22=$J$17,TRUE,FALSE) -> FALSE | L22: 작업발판 | M22: =IF($L$17=L22,TRUE,FALSE) -> FALSE | N22: 보호구 | O22: =IF($N$17=N22,TRUE,FALSE) -> FALSE | P22: 위험을 생각하지 않음 | Q22: =IF($P$17=P22,TRUE,FALSE) -> FALSE | R22: 자만심 | S22: =IF($R$17=R22,TRUE,FALSE) -> FALSE
J23: 비래 | K23: =IF(J23=$J$17,TRUE,FALSE) -> FALSE | L23: 개구부 | M23: =IF($L$17=L23,TRUE,FALSE) -> FALSE | N23: 불안전한 자세 | O23: =IF($N$17=N23,TRUE,FALSE) -> FALSE
J24: 붕괴 | K24: =IF(J24=$J$17,TRUE,FALSE) -> FALSE | L24: 전기 | M24: =IF($L$17=L24,TRUE,FALSE) -> FALSE | N24: 소통 미비 | O24: =IF($N$17=N24,TRUE,FALSE) -> FALSE
J25: 협착 | K25: =IF(J25=$J$17,TRUE,FALSE) -> FALSE | L25: 운전장비 | M25: =IF($L$17=L25,TRUE,FALSE) -> FALSE | N25: 평소 습관 | O25: =IF($N$17=N25,TRUE,FALSE) -> FALSE
J26: 감전 | K26: =IF(J26=$J$17,TRUE,FALSE) -> FALSE | L26: 설비 | M26: =IF($L$17=L26,TRUE,FALSE) -> FALSE | N26: 기타 | O26: =IF(COUNTIF(N17,"*기타*"),TRUE,FALSE) -> TRUE
D27: 불안전한 행동 : | J27: 요통 | K27: =IF(J27=$J$17,TRUE,FALSE) -> FALSE | L27: 정리정돈 | M27: =IF($L$17=L27,TRUE,FALSE) -> FALSE
J28: 화상/동상 | K28: =IF(J28=$J$17,TRUE,FALSE) -> FALSE | L28: 자연재해 | M28: =IF($L$17=L28,TRUE,FALSE) -> FALSE
J29: 기타 | K29: =IF(J29=$J$17,TRUE,FALSE) -> FALSE | L29: 기타 | M29: =IF($L$17=L29,TRUE,FALSE) -> FALSE
J30: 설비 사고 | K30: =IF(J30=$J$17,TRUE,FALSE) -> FALSE | L30: 계단 | M30: =IF($L$17=L30,TRUE,FALSE) -> FALSE
J31: 유해물질 접촉 | K31: =IF(J31=$J$17,TRUE,FALSE) -> FALSE | L31: 낙석 | M31: =IF($L$17=L31,TRUE,FALSE) -> FALSE
J32: 화재/ 폭발 | K32: =IF(J32=$J$17,TRUE,FALSE) -> FALSE | L32: 폭설/ 결빙 | M32: =IF($L$17=L32,TRUE,FALSE) -> FALSE
J33: 익사 | K33: =IF(J33=$J$17,TRUE,FALSE) -> FALSE | L33: 도구 및 장비 | M33: =IF($L$17=L33,TRUE,FALSE) -> FALSE
J34: 절단/ 찰과상 | K34: =IF(J34=$J$17,TRUE,FALSE) -> FALSE | L34: 동물/ 뱀/ 벌 | M34: =IF($L$17=L34,TRUE,FALSE) -> FALSE
A35: 사고 방지를 위해 | B35: ※ 보고자가 조치한 사항이 있는경우에 기록 해 주시기 바랍니다. | J35: 분류 불능 | K35: =IF(J35=$J$17,TRUE,FALSE) -> FALSE | L35: 제3자 | M35: =IF($L$17=L35,TRUE,FALSE) -> FALSE
A36: 저는 이렇게 | B36: =_xlfn.LET( _xlpm.RESULT, _xlfn.XLOOKUP(B7,near_miss_excel_view!C:C,near_miss_excel_view!N:N,"없음",0,1), _xlpm.ANOTHER, _xlfn.XLOOKUP(B7,near_miss_excel_view!C:C,near_miss_excel_view!M:M,"없음",0,1), IF(_xlpm.RESULT="",_xlpm.ANOTHER,_xlpm.RESULT)) -> 고여있던 물들을 벨트를 꾹 눌러 밑으로 흘려보내고 부석들도 땅으로 밀어 치워둠 | J36: 차량사고 | K36: =IF(J36=$J$17,TRUE,FALSE) -> FALSE | L36: 조명/ 환경 | M36: =IF($L$17=L36,TRUE,FALSE) -> FALSE
A37: 조치하였습니다
A39: ▶ 제안자는 위의 사항들만 작성하시어 관련팀에 제출하여 주시기 바랍니다.
A40: 다음과 같은 | B40: ※ 아차사고확인자(접수팀)에 의해 수립된 계획
A41: 조치를 취해
A42: 주시기 바랍니다
A44: 제안사항 확인 | B44: 접수팀 | C44: (인) | F44: 안전관리팀으로 제출 후 개선계획을 기록/보관하여 주시기 바랍니다.
A45: ▶ 접수팀에서는 접수 즉시 안전보건팀으로 제출하여 주시기 바랍니다.
A46: 접수 확인 | B46: 안전관리팀 | C46: (인)
A47: ▶ 접수팀에서는 팀장 확인 후 자체 보관하여 주시기 바랍니다.
...

Sheet 보고서(4-15)
B1: (■ 아차사고 , □ 응급처치 ) 보고서
A3: ■ 아차사고 보고서를 이용하여, 상황이 다소 달랐다면 인명피해로 이어질수 있었던 사고를 보고해 주시기 바랍니다
A4: ■ 여러분의 협조가 당사의 인적, 물적 피해를 줄일 수 있으며 예방하는 도움이 됩니다
H5: ="작성일 : "&TEXT(_xlfn.XLOOKUP(B7,near_miss_excel_view!C:C,near_miss_excel_view!D:D,"없음",0,1),"YY-MM-DD") -> 작성일 : 26-04-15
A6: 소 속 | B6: 현대기전 | D6: 성 명 | E6: =_xlfn.XLOOKUP(B7,near_miss_excel_view!C:C,near_miss_excel_view!B:B,"없음",0,1) -> 이정민 | G6: 사 번
A7: 아차사고명 | B7: 그라인더 작업 중 쉿가루 튐
A9: 아차사고 | B9: =" 1. 발생 일시 : "&TEXT(_xlfn.XLOOKUP(B7,near_miss_excel_view!C:C,near_miss_excel_view!D:D,"없음",0,1),"YYYY년 MM월 DD일 hh시 mm분")&" 경" -> 1. 발생 일시 : 2026년 04월 15일 10시 30분 경
A10: 경험(목격) | B10: =" 2. 발생 장소 : "&_xlfn.XLOOKUP(B7,near_miss_excel_view!C:C,near_miss_excel_view!E:E,"없음",0,1) -> 2. 발생 장소 : 광산 bc2 벨트
A11: 내용 및 | B11: {=" 3. 내용 / 원인 : "&_xlfn.XLOOKUP(B7,near_miss_excel_view!C:C,CHAR(10)&"내용: "&near_miss_excel_view!F:F&CHAR(10)&"원인: "&near_miss_excel_view!G:G,"없음",0,1)} -> 3. 내용 / 원인 : 내용: 트레이 작업 중 그라인더로 잔넬을 절단하던 중 쉿가루가 눈으로 튐 원인: 눈에는 보안경을 착용하고 있었지만 자르는 행위 중 아래를 보면서 작업을 해야했고 보안경이 조금씩 흘러내리는 사이 눈으로 튐
A12: 원인 입니다
J16: 사고유형 | L16: 불안전한상태 | N16: 불안전한행동 | P16: 부주의 행동 | R16: 부주의 상태
A17: 다음 해당하는 사항에 체크하세요. | J17: =_xlfn.XLOOKUP(B7,near_miss_excel_view!$C:$C,near_miss_excel_view!H:H,"없음",0,1) -> 유해물질 접촉 | L17: =_xlfn.XLOOKUP(B7,near_miss_excel_view!$C:$C,near_miss_excel_view!I:I,"없음",0,1) -> 기타 | N17: =_xlfn.XLOOKUP(B7,near_miss_excel_view!$C:$C,near_miss_excel_view!J:J,"없음",0,1) -> 불안전한 자세 | P17: =_xlfn.XLOOKUP(B7,near_miss_excel_view!$C:$C,near_miss_excel_view!K:K,"없음",0,1) -> 위험을 생각하지 않음 | R17: =_xlfn.XLOOKUP(B7,near_miss_excel_view!$C:$C,near_miss_excel_view!L:L,"없음",0,1) -> 자만심
A18: 사고 유형 | D18: 불안전한 상태 :
J19: 추락 | K19: =IF(J19=$J$17,TRUE,FALSE) -> FALSE | L19: 통로 | M19: =IF($L$17=L19,TRUE,FALSE) -> FALSE | N19: 규정위반 | O19: =IF($N$17=N19,TRUE,FALSE) -> FALSE | P19: 위험경로에 위치함 | Q19: =IF($P$17=P19,TRUE,FALSE) -> FALSE | R19: 서두름 | S19: =IF($R$17=R19,TRUE,FALSE) -> FALSE
J20: 전도 | K20: =IF(J20=$J$17,TRUE,FALSE) -> FALSE | L20: 돌출부 | M20: =IF($L$17=L20,TRUE,FALSE) -> FALSE | N20: 도구의 잘못 사용 | O20: =IF($N$17=N20,TRUE,FALSE) -> FALSE | P20: 몸의 균형이 불안정해짐 | Q20: =IF($P$17=P20,TRUE,FALSE) -> FALSE | R20: 피로 | S20: =IF($R$17=R20,TRUE,FALSE) -> FALSE
J21: 충돌 | K21: =IF(J21=$J$17,TRUE,FALSE) -> FALSE | L21: 안전난간 | M21: =IF($L$17=L21,TRUE,FALSE) -> FALSE | N21: 무거운 짐 취급 | O21: =IF($N$17=N21,TRUE,FALSE) -> FALSE | P21: 위험을 보지 않음 | Q21: =IF($P$17=P21,TRUE,FALSE) -> FALSE | R21: 스트레스 | S21: =IF($R$17=R21,TRUE,FALSE) -> FALSE
J22: 낙하 | K22: =IF(J22=$J$17,TRUE,FALSE) -> FALSE | L22: 작업발판 | M22: =IF($L$17=L22,TRUE,FALSE) -> FALSE | N22: 보호구 | O22: =IF($N$17=N22,TRUE,FALSE) -> FALSE | P22: 위험을 생각하지 않음 | Q22: =IF($P$17=P22,TRUE,FALSE) -> TRUE | R22: 자만심 | S22: =IF($R$17=R22,TRUE,FALSE) -> TRUE
J23: 비래 | K23: =IF(J23=$J$17,TRUE,FALSE) -> FALSE | L23: 개구부 | M23: =IF($L$17=L23,TRUE,FALSE) -> FALSE | N23: 불안전한 자세 | O23: =IF($N$17=N23,TRUE,FALSE) -> TRUE
J24: 붕괴 | K24: =IF(J24=$J$17,TRUE,FALSE) -> FALSE | L24: 전기 | M24: =IF($L$17=L24,TRUE,FALSE) -> FALSE | N24: 소통 미비 | O24: =IF($N$17=N24,TRUE,FALSE) -> FALSE
J25: 협착 | K25: =IF(J25=$J$17,TRUE,FALSE) -> FALSE | L25: 운전장비 | M25: =IF($L$17=L25,TRUE,FALSE) -> FALSE | N25: 평소 습관 | O25: =IF($N$17=N25,TRUE,FALSE) -> FALSE
J26: 감전 | K26: =IF(J26=$J$17,TRUE,FALSE) -> FALSE | L26: 설비 | M26: =IF($L$17=L26,TRUE,FALSE) -> FALSE | N26: 기타 | O26: =IF($N$17=N26,TRUE,FALSE) -> FALSE
D27: 불안전한 행동 : | J27: 요통 | K27: =IF(J27=$J$17,TRUE,FALSE) -> FALSE | L27: 정리정돈 | M27: =IF($L$17=L27,TRUE,FALSE) -> FALSE
J28: 화상/동상 | K28: =IF(J28=$J$17,TRUE,FALSE) -> FALSE | L28: 자연재해 | M28: =IF($L$17=L28,TRUE,FALSE) -> FALSE
J29: 기타 | K29: =IF(J29=$J$17,TRUE,FALSE) -> FALSE | L29: 기타 | M29: =IF($L$17=L29,TRUE,FALSE) -> TRUE
J30: 설비 사고 | K30: =IF(J30=$J$17,TRUE,FALSE) -> FALSE | L30: 계단 | M30: =IF($L$17=L30,TRUE,FALSE) -> FALSE
J31: 유해물질 접촉 | K31: =IF(J31=$J$17,TRUE,FALSE) -> TRUE | L31: 낙석 | M31: =IF($L$17=L31,TRUE,FALSE) -> FALSE
J32: 화재/ 폭발 | K32: =IF(J32=$J$17,TRUE,FALSE) -> FALSE | L32: 폭설/ 결빙 | M32: =IF($L$17=L32,TRUE,FALSE) -> FALSE
J33: 익사 | K33: =IF(J33=$J$17,TRUE,FALSE) -> FALSE | L33: 도구 및 장비 | M33: =IF($L$17=L33,TRUE,FALSE) -> FALSE
J34: 절단/ 찰과상 | K34: =IF(J34=$J$17,TRUE,FALSE) -> FALSE | L34: 동물/ 뱀/ 벌 | M34: =IF($L$17=L34,TRUE,FALSE) -> FALSE
A35: 사고 방지를 위해 | B35: ※ 보고자가 조치한 사항이 있는경우에 기록 해 주시기 바랍니다. | J35: 분류 불능 | K35: =IF(J35=$J$17,TRUE,FALSE) -> FALSE | L35: 제3자 | M35: =IF($L$17=L35,TRUE,FALSE) -> FALSE
A36: 저는 이렇게 | B36: =_xlfn.LET( _xlpm.RESULT, _xlfn.XLOOKUP(B7,near_miss_excel_view!C:C,near_miss_excel_view!N:N,"없음",0,1), _xlpm.ANOTHER, _xlfn.XLOOKUP(B7,near_miss_excel_view!C:C,near_miss_excel_view!M:M,"없음",0,1), IF(_xlpm.RESULT="",_xlpm.ANOTHER,_xlpm.RESULT)) -> 보안경을 바르게 착용하고 내 자세를 딱 고정할 수 있는 위치에서 작업시행 | J36: 차량사고 | K36: =IF(J36=$J$17,TRUE,FALSE) -> FALSE | L36: 조명/ 환경 | M36: =IF($L$17=L36,TRUE,FALSE) -> FALSE
A37: 조치하였습니다
A39: ▶ 제안자는 위의 사항들만 작성하시어 관련팀에 제출하여 주시기 바랍니다.
A40: 다음과 같은 | B40: ※ 아차사고확인자(접수팀)에 의해 수립된 계획
A41: 조치를 취해
A42: 주시기 바랍니다
A44: 제안사항 확인 | B44: 접수팀 | C44: (인) | F44: 안전관리팀으로 제출 후 개선계획을 기록/보관하여 주시기 바랍니다.
A45: ▶ 접수팀에서는 접수 즉시 안전보건팀으로 제출하여 주시기 바랍니다.
A46: 접수 확인 | B46: 안전관리팀 | C46: (인)
A47: ▶ 접수팀에서는 팀장 확인 후 자체 보관하여 주시기 바랍니다.
...

Sheet 보고서(4-16)
B1: (■ 아차사고 , □ 응급처치 ) 보고서
A3: ■ 아차사고 보고서를 이용하여, 상황이 다소 달랐다면 인명피해로 이어질수 있었던 사고를 보고해 주시기 바랍니다
A4: ■ 여러분의 협조가 당사의 인적, 물적 피해를 줄일 수 있으며 예방하는 도움이 됩니다
H5: ="작성일 : "&TEXT(_xlfn.XLOOKUP(B7,near_miss_excel_view!C:C,near_miss_excel_view!D:D,"없음",0,1),"YY-MM-DD") -> 작성일 : 26-04-16
A6: 소 속 | B6: 현대기전 | D6: 성 명 | E6: =_xlfn.XLOOKUP(B7,near_miss_excel_view!C:C,near_miss_excel_view!B:B,"없음",0,1) -> 정재호 | G6: 사 번
A7: 아차사고명 | B7: 사다리 이동중 무릎, 팔 타박상
A9: 아차사고 | B9: =" 1. 발생 일시 : "&TEXT(_xlfn.XLOOKUP(B7,near_miss_excel_view!C:C,near_miss_excel_view!D:D,"없음",0,1),"YYYY년 MM월 DD일 hh시 mm분")&" 경" -> 1. 발생 일시 : 2026년 04월 16일 23시 00분 경
A10: 경험(목격) | B10: =" 2. 발생 장소 : "&_xlfn.XLOOKUP(B7,near_miss_excel_view!C:C,near_miss_excel_view!E:E,"없음",0,1) -> 2. 발생 장소 : 4호 coal mill probe 위치
A11: 내용 및 | B11: {=" 3. 내용 / 원인 : "&_xlfn.XLOOKUP(B7,near_miss_excel_view!C:C,CHAR(10)&"내용: "&near_miss_excel_view!F:F&CHAR(10)&"원인: "&near_miss_excel_view!G:G,"없음",0,1)} -> 3. 내용 / 원인 : 내용: 야간에 사다리 이동 중 부딪힘 원인: 조도가 낮은 상태에서 주변 확인을 하지 못함
A12: 원인 입니다
J16: 사고유형 | L16: 불안전한상태 | N16: 불안전한행동 | P16: 부주의 행동 | R16: 부주의 상태
A17: 다음 해당하는 사항에 체크하세요. | J17: =_xlfn.XLOOKUP(B7,near_miss_excel_view!$C:$C,near_miss_excel_view!H:H,"없음",0,1) -> 충돌 | L17: =_xlfn.XLOOKUP(B7,near_miss_excel_view!$C:$C,near_miss_excel_view!I:I,"없음",0,1) -> 돌출부 | N17: =_xlfn.XLOOKUP(B7,near_miss_excel_view!$C:$C,near_miss_excel_view!J:J,"없음",0,1) -> 기타 | P17: =_xlfn.XLOOKUP(B7,near_miss_excel_view!$C:$C,near_miss_excel_view!K:K,"없음",0,1) -> 몸의 균형이 불안정해짐 | R17: =_xlfn.XLOOKUP(B7,near_miss_excel_view!$C:$C,near_miss_excel_view!L:L,"없음",0,1) -> 서두름
A18: 사고 유형 | D18: 불안전한 상태 :
J19: 추락 | K19: =IF(J19=$J$17,TRUE,FALSE) -> FALSE | L19: 통로 | M19: =IF($L$17=L19,TRUE,FALSE) -> FALSE | N19: 규정위반 | O19: =IF($N$17=N19,TRUE,FALSE) -> FALSE | P19: 위험경로에 위치함 | Q19: =IF($P$17=P19,TRUE,FALSE) -> FALSE | R19: 서두름 | S19: =IF($R$17=R19,TRUE,FALSE) -> TRUE
J20: 전도 | K20: =IF(J20=$J$17,TRUE,FALSE) -> FALSE | L20: 돌출부 | M20: =IF($L$17=L20,TRUE,FALSE) -> TRUE | N20: 도구의 잘못 사용 | O20: =IF($N$17=N20,TRUE,FALSE) -> FALSE | P20: 몸의 균형이 불안정해짐 | Q20: =IF($P$17=P20,TRUE,FALSE) -> TRUE | R20: 피로 | S20: =IF($R$17=R20,TRUE,FALSE) -> FALSE
J21: 충돌 | K21: =IF(J21=$J$17,TRUE,FALSE) -> TRUE | L21: 안전난간 | M21: =IF($L$17=L21,TRUE,FALSE) -> FALSE | N21: 무거운 짐 취급 | O21: =IF($N$17=N21,TRUE,FALSE) -> FALSE | P21: 위험을 보지 않음 | Q21: =IF($P$17=P21,TRUE,FALSE) -> FALSE | R21: 스트레스 | S21: =IF($R$17=R21,TRUE,FALSE) -> FALSE
J22: 낙하 | K22: =IF(J22=$J$17,TRUE,FALSE) -> FALSE | L22: 작업발판 | M22: =IF($L$17=L22,TRUE,FALSE) -> FALSE | N22: 보호구 | O22: =IF($N$17=N22,TRUE,FALSE) -> FALSE | P22: 위험을 생각하지 않음 | Q22: =IF($P$17=P22,TRUE,FALSE) -> FALSE | R22: 자만심 | S22: =IF($R$17=R22,TRUE,FALSE) -> FALSE
J23: 비래 | K23: =IF(J23=$J$17,TRUE,FALSE) -> FALSE | L23: 개구부 | M23: =IF($L$17=L23,TRUE,FALSE) -> FALSE | N23: 불안전한 자세 | O23: =IF($N$17=N23,TRUE,FALSE) -> FALSE
J24: 붕괴 | K24: =IF(J24=$J$17,TRUE,FALSE) -> FALSE | L24: 전기 | M24: =IF($L$17=L24,TRUE,FALSE) -> FALSE | N24: 소통 미비 | O24: =IF($N$17=N24,TRUE,FALSE) -> FALSE
J25: 협착 | K25: =IF(J25=$J$17,TRUE,FALSE) -> FALSE | L25: 운전장비 | M25: =IF($L$17=L25,TRUE,FALSE) -> FALSE | N25: 평소 습관 | O25: =IF($N$17=N25,TRUE,FALSE) -> FALSE
J26: 감전 | K26: =IF(J26=$J$17,TRUE,FALSE) -> FALSE | L26: 설비 | M26: =IF($L$17=L26,TRUE,FALSE) -> FALSE | N26: 기타 | O26: =IF($N$17=N26,TRUE,FALSE) -> TRUE
D27: 불안전한 행동 : | J27: 요통 | K27: =IF(J27=$J$17,TRUE,FALSE) -> FALSE | L27: 정리정돈 | M27: =IF($L$17=L27,TRUE,FALSE) -> FALSE
J28: 화상/동상 | K28: =IF(J28=$J$17,TRUE,FALSE) -> FALSE | L28: 자연재해 | M28: =IF($L$17=L28,TRUE,FALSE) -> FALSE
J29: 기타 | K29: =IF(J29=$J$17,TRUE,FALSE) -> FALSE | L29: 기타 | M29: =IF($L$17=L29,TRUE,FALSE) -> FALSE
J30: 설비 사고 | K30: =IF(J30=$J$17,TRUE,FALSE) -> FALSE | L30: 계단 | M30: =IF($L$17=L30,TRUE,FALSE) -> FALSE
J31: 유해물질 접촉 | K31: =IF(J31=$J$17,TRUE,FALSE) -> FALSE | L31: 낙석 | M31: =IF($L$17=L31,TRUE,FALSE) -> FALSE
J32: 화재/ 폭발 | K32: =IF(J32=$J$17,TRUE,FALSE) -> FALSE | L32: 폭설/ 결빙 | M32: =IF($L$17=L32,TRUE,FALSE) -> FALSE
J33: 익사 | K33: =IF(J33=$J$17,TRUE,FALSE) -> FALSE | L33: 도구 및 장비 | M33: =IF($L$17=L33,TRUE,FALSE) -> FALSE
J34: 절단/ 찰과상 | K34: =IF(J34=$J$17,TRUE,FALSE) -> FALSE | L34: 동물/ 뱀/ 벌 | M34: =IF($L$17=L34,TRUE,FALSE) -> FALSE
A35: 사고 방지를 위해 | B35: ※ 보고자가 조치한 사항이 있는경우에 기록 해 주시기 바랍니다. | J35: 분류 불능 | K35: =IF(J35=$J$17,TRUE,FALSE) -> FALSE | L35: 제3자 | M35: =IF($L$17=L35,TRUE,FALSE) -> FALSE
A36: 저는 이렇게 | B36: =_xlfn.LET( _xlpm.RESULT, _xlfn.XLOOKUP(B7,near_miss_excel_view!C:C,near_miss_excel_view!N:N,"없음",0,1), _xlpm.ANOTHER, _xlfn.XLOOKUP(B7,near_miss_excel_view!C:C,near_miss_excel_view!M:M,"없음",0,1), IF(_xlpm.RESULT="",_xlpm.ANOTHER,_xlpm.RESULT)) -> 야간작업중 사다리 이동 시 해드랜턴 항시 켜놓은 후 돌출부 확인 및 접지 부 확인 철저 | J36: 차량사고 | K36: =IF(J36=$J$17,TRUE,FALSE) -> FALSE | L36: 조명/ 환경 | M36: =IF($L$17=L36,TRUE,FALSE) -> FALSE
A37: 조치하였습니다
A39: ▶ 제안자는 위의 사항들만 작성하시어 관련팀에 제출하여 주시기 바랍니다.
A40: 다음과 같은 | B40: ※ 아차사고확인자(접수팀)에 의해 수립된 계획
A41: 조치를 취해
A42: 주시기 바랍니다
A44: 제안사항 확인 | B44: 접수팀 | C44: (인) | F44: 안전관리팀으로 제출 후 개선계획을 기록/보관하여 주시기 바랍니다.
A45: ▶ 접수팀에서는 접수 즉시 안전보건팀으로 제출하여 주시기 바랍니다.
A46: 접수 확인 | B46: 안전관리팀 | C46: (인)
A47: ▶ 접수팀에서는 팀장 확인 후 자체 보관하여 주시기 바랍니다.
...

Sheet 보고서(4-18)
B1: (■ 아차사고 , □ 응급처치 ) 보고서
A3: ■ 아차사고 보고서를 이용하여, 상황이 다소 달랐다면 인명피해로 이어질수 있었던 사고를 보고해 주시기 바랍니다
A4: ■ 여러분의 협조가 당사의 인적, 물적 피해를 줄일 수 있으며 예방하는 도움이 됩니다
H5: ="작성일 : "&TEXT(_xlfn.XLOOKUP(B7,near_miss_excel_view!C:C,near_miss_excel_view!D:D,"없음",0,1),"YY-MM-DD") -> 작성일 : 26-04-18
A6: 소 속 | B6: 현대기전 | D6: 성 명 | E6: =_xlfn.XLOOKUP(B7,near_miss_excel_view!C:C,near_miss_excel_view!B:B,"없음",0,1) -> 이윤성 | G6: 사 번
A7: 아차사고명 | B7: 4k kiln inlet 계단 올라갈 때 배관에 헬멧 박아서 계단에서 넘어질 뻔함
A9: 아차사고 | B9: =" 1. 발생 일시 : "&TEXT(_xlfn.XLOOKUP(B7,near_miss_excel_view!C:C,near_miss_excel_view!D:D,"없음",0,1),"YYYY년 MM월 DD일 hh시 mm분")&" 경" -> 1. 발생 일시 : 2026년 04월 18일 22시 40분 경
A10: 경험(목격) | B10: =" 2. 발생 장소 : "&_xlfn.XLOOKUP(B7,near_miss_excel_view!C:C,near_miss_excel_view!E:E,"없음",0,1) -> 2. 발생 장소 : 4k kiln inlet 앞 계단
A11: 내용 및 | B11: {=" 3. 내용 / 원인 : "&_xlfn.XLOOKUP(B7,near_miss_excel_view!C:C,CHAR(10)&"내용: "&near_miss_excel_view!F:F&CHAR(10)&"원인: "&near_miss_excel_view!G:G,"없음",0,1)} -> 3. 내용 / 원인 : 내용: 4k kiln inlet Probe 점검하러 올라가려는 계단에 위치한 배관에 헬멧을 박아서 뒤로 넘어질 뻔한 사고 발생 원인: 계단 위치에 있는 배관이 너무 낮게 되어 있습니다.
A12: 원인 입니다
J16: 사고유형 | L16: 불안전한상태 | N16: 불안전한행동 | P16: 부주의 행동 | R16: 부주의 상태
A17: 다음 해당하는 사항에 체크하세요. | J17: =_xlfn.XLOOKUP(B7,near_miss_excel_view!$C:$C,near_miss_excel_view!H:H,"없음",0,1) -> 충돌 | L17: =_xlfn.XLOOKUP(B7,near_miss_excel_view!$C:$C,near_miss_excel_view!I:I,"없음",0,1) -> 계단 | N17: =_xlfn.XLOOKUP(B7,near_miss_excel_view!$C:$C,near_miss_excel_view!J:J,"없음",0,1) -> 불안전한 자세 | P17: =_xlfn.XLOOKUP(B7,near_miss_excel_view!$C:$C,near_miss_excel_view!K:K,"없음",0,1) -> 위험을 생각하지 않음 | R17: =_xlfn.XLOOKUP(B7,near_miss_excel_view!$C:$C,near_miss_excel_view!L:L,"없음",0,1) -> 서두름
A18: 사고 유형 | D18: 불안전한 상태 :
J19: 추락 | K19: =IF(J19=$J$17,TRUE,FALSE) -> FALSE | L19: 통로 | M19: =IF($L$17=L19,TRUE,FALSE) -> FALSE | N19: 규정위반 | O19: =IF($N$17=N19,TRUE,FALSE) -> FALSE | P19: 위험경로에 위치함 | Q19: =IF($P$17=P19,TRUE,FALSE) -> FALSE | R19: 서두름 | S19: =IF($R$17=R19,TRUE,FALSE) -> TRUE
J20: 전도 | K20: =IF(J20=$J$17,TRUE,FALSE) -> FALSE | L20: 돌출부 | M20: FALSE | N20: 도구의 잘못 사용 | O20: =IF($N$17=N20,TRUE,FALSE) -> FALSE | P20: 몸의 균형이 불안정해짐 | Q20: =IF($P$17=P20,TRUE,FALSE) -> FALSE | R20: 피로 | S20: =IF($R$17=R20,TRUE,FALSE) -> FALSE
J21: 충돌 | K21: =IF(J21=$J$17,TRUE,FALSE) -> TRUE | L21: 안전난간 | M21: =IF($L$17=L21,TRUE,FALSE) -> FALSE | N21: 무거운 짐 취급 | O21: =IF($N$17=N21,TRUE,FALSE) -> FALSE | P21: 위험을 보지 않음 | Q21: =IF($P$17=P21,TRUE,FALSE) -> FALSE | R21: 스트레스 | S21: =IF($R$17=R21,TRUE,FALSE) -> FALSE
J22: 낙하 | K22: =IF(J22=$J$17,TRUE,FALSE) -> FALSE | L22: 작업발판 | M22: FALSE | N22: 보호구 | O22: =IF($N$17=N22,TRUE,FALSE) -> FALSE | P22: 위험을 생각하지 않음 | Q22: =IF($P$17=P22,TRUE,FALSE) -> TRUE | R22: 자만심 | S22: =IF($R$17=R22,TRUE,FALSE) -> FALSE
J23: 비래 | K23: =IF(J23=$J$17,TRUE,FALSE) -> FALSE | L23: 개구부 | M23: FALSE | N23: 불안전한 자세 | O23: =IF($N$17=N23,TRUE,FALSE) -> TRUE
J24: 붕괴 | K24: =IF(J24=$J$17,TRUE,FALSE) -> FALSE | L24: 전기 | M24: FALSE | N24: 소통 미비 | O24: =IF($N$17=N24,TRUE,FALSE) -> FALSE
J25: 협착 | K25: =IF(J25=$J$17,TRUE,FALSE) -> FALSE | L25: 운전장비 | M25: =IF($L$17=L25,TRUE,FALSE) -> FALSE | N25: 평소 습관 | O25: =IF($N$17=N25,TRUE,FALSE) -> FALSE
J26: 감전 | K26: =IF(J26=$J$17,TRUE,FALSE) -> FALSE | L26: 설비 | M26: =IF($L$17=L26,TRUE,FALSE) -> FALSE | N26: 기타 | O26: =IF($N$17=N26,TRUE,FALSE) -> FALSE
D27: 불안전한 행동 : | J27: 요통 | K27: =IF(J27=$J$17,TRUE,FALSE) -> FALSE | L27: 정리정돈 | M27: =IF($L$17=L27,TRUE,FALSE) -> FALSE
J28: 화상/동상 | K28: =IF(J28=$J$17,TRUE,FALSE) -> FALSE | L28: 자연재해 | M28: =IF($L$17=L28,TRUE,FALSE) -> FALSE
J29: 기타 | K29: =IF(J29=$J$17,TRUE,FALSE) -> FALSE | L29: 기타 | M29: =IF($L$17=L29,TRUE,FALSE) -> FALSE
J30: 설비 사고 | K30: =IF(J30=$J$17,TRUE,FALSE) -> FALSE | L30: 계단 | M30: =IF($L$17=L30,TRUE,FALSE) -> TRUE
J31: 유해물질 접촉 | K31: =IF(J31=$J$17,TRUE,FALSE) -> FALSE | L31: 낙석 | M31: =IF($L$17=L31,TRUE,FALSE) -> FALSE
J32: 화재/ 폭발 | K32: =IF(J32=$J$17,TRUE,FALSE) -> FALSE | L32: 폭설/ 결빙 | M32: =IF($L$17=L32,TRUE,FALSE) -> FALSE
J33: 익사 | K33: =IF(J33=$J$17,TRUE,FALSE) -> FALSE | L33: 도구 및 장비 | M33: =IF($L$17=L33,TRUE,FALSE) -> FALSE
J34: 절단/ 찰과상 | K34: =IF(J34=$J$17,TRUE,FALSE) -> FALSE | L34: 동물/ 뱀/ 벌 | M34: =IF($L$17=L34,TRUE,FALSE) -> FALSE
A35: 사고 방지를 위해 | B35: ※ 보고자가 조치한 사항이 있는경우에 기록 해 주시기 바랍니다. | J35: 분류 불능 | K35: =IF(J35=$J$17,TRUE,FALSE) -> FALSE | L35: 제3자 | M35: =IF($L$17=L35,TRUE,FALSE) -> FALSE
A36: 저는 이렇게 | B36: =_xlfn.LET( _xlpm.RESULT, _xlfn.XLOOKUP(B7,near_miss_excel_view!C:C,near_miss_excel_view!N:N,"없음",0,1), _xlpm.ANOTHER, _xlfn.XLOOKUP(B7,near_miss_excel_view!C:C,near_miss_excel_view!M:M,"없음",0,1), IF(_xlpm.RESULT="",_xlpm.ANOTHER,_xlpm.RESULT)) -> 재발을 방지하기 위해 헤드 라이트를 사용 후 고개와 허리를 숙이며 안전 난간을 잡고 조심히 이동하였습니다. | J36: 차량사고 | K36: =IF(J36=$J$17,TRUE,FALSE) -> FALSE | L36: 조명/ 환경 | M36: =IF($L$17=L36,TRUE,FALSE) -> FALSE
A37: 조치하였습니다
A39: ▶ 제안자는 위의 사항들만 작성하시어 관련팀에 제출하여 주시기 바랍니다.
A40: 다음과 같은 | B40: ※ 아차사고확인자(접수팀)에 의해 수립된 계획
A41: 조치를 취해
A42: 주시기 바랍니다
A44: 제안사항 확인 | B44: 접수팀 | C44: (인) | F44: 안전관리팀으로 제출 후 개선계획을 기록/보관하여 주시기 바랍니다.
A45: ▶ 접수팀에서는 접수 즉시 안전보건팀으로 제출하여 주시기 바랍니다.
A46: 접수 확인 | B46: 안전관리팀 | C46: (인)
A47: ▶ 접수팀에서는 팀장 확인 후 자체 보관하여 주시기 바랍니다.
...

Sheet 보고서(4-28)
B1: (■ 아차사고 , □ 응급처치 ) 보고서
A3: ■ 아차사고 보고서를 이용하여, 상황이 다소 달랐다면 인명피해로 이어질수 있었던 사고를 보고해 주시기 바랍니다
A4: ■ 여러분의 협조가 당사의 인적, 물적 피해를 줄일 수 있으며 예방하는 도움이 됩니다
H5: ="작성일 : "&TEXT(_xlfn.XLOOKUP(B7,near_miss_excel_view!C:C,near_miss_excel_view!D:D,"없음",0,1),"YY-MM-DD") -> 작성일 : 26-04-28
A6: 소 속 | B6: 현대기전 | D6: 성 명 | E6: =_xlfn.XLOOKUP(B7,near_miss_excel_view!C:C,near_miss_excel_view!B:B,"없음",0,1) -> 김동훈 | G6: 사 번
A7: 아차사고명 | B7: 작업중 부딪침.
A9: 아차사고 | B9: =" 1. 발생 일시 : "&TEXT(_xlfn.XLOOKUP(B7,near_miss_excel_view!C:C,near_miss_excel_view!D:D,"없음",0,1),"YYYY년 MM월 DD일 hh시 mm분")&" 경" -> 1. 발생 일시 : 2026년 04월 28일 23시 25분 경
A10: 경험(목격) | B10: =" 2. 발생 장소 : "&_xlfn.XLOOKUP(B7,near_miss_excel_view!C:C,near_miss_excel_view!E:E,"없음",0,1) -> 2. 발생 장소 : 2호 IDF PROBE 앞.
A11: 내용 및 | B11: {=" 3. 내용 / 원인 : "&_xlfn.XLOOKUP(B7,near_miss_excel_view!C:C,CHAR(10)&"내용: "&near_miss_excel_view!F:F&CHAR(10)&"원인: "&near_miss_excel_view!G:G,"없음",0,1)} -> 3. 내용 / 원인 : 내용: IDF 펌프 및 라인 청소 중 조도 문제로 바닥 구조물에 부딪치고 넘어질 뻔 함. 원인: 작업중 부주의하여 부딪침.
A12: 원인 입니다
J16: 사고유형 | L16: 불안전한상태 | N16: 불안전한행동 | P16: 부주의 행동 | R16: 부주의 상태
A17: 다음 해당하는 사항에 체크하세요. | J17: =_xlfn.XLOOKUP(B7,near_miss_excel_view!$C:$C,near_miss_excel_view!H:H,"없음",0,1) -> 충돌 | L17: =_xlfn.XLOOKUP(B7,near_miss_excel_view!$C:$C,near_miss_excel_view!I:I,"없음",0,1) -> 조명/환경 | N17: =_xlfn.XLOOKUP(B7,near_miss_excel_view!$C:$C,near_miss_excel_view!J:J,"없음",0,1) -> 기타: 부주의 | P17: =_xlfn.XLOOKUP(B7,near_miss_excel_view!$C:$C,near_miss_excel_view!K:K,"없음",0,1) -> 위험을 생각하지 않음 | R17: =_xlfn.XLOOKUP(B7,near_miss_excel_view!$C:$C,near_miss_excel_view!L:L,"없음",0,1) -> 서두름
A18: 사고 유형 | D18: 불안전한 상태 :
J19: 추락 | K19: =IF(J19=$J$17,TRUE,FALSE) -> FALSE | L19: 통로 | M19: =IF($L$17=L19,TRUE,FALSE) -> FALSE | N19: 규정위반 | O19: =IF($N$17=N19,TRUE,FALSE) -> FALSE | P19: 위험경로에 위치함 | Q19: =IF($P$17=P19,TRUE,FALSE) -> FALSE | R19: 서두름 | S19: =IF($R$17=R19,TRUE,FALSE) -> TRUE
J20: 전도 | K20: =IF(J20=$J$17,TRUE,FALSE) -> FALSE | L20: 돌출부 | M20: FALSE | N20: 도구의 잘못 사용 | O20: =IF($N$17=N20,TRUE,FALSE) -> FALSE | P20: 몸의 균형이 불안정해짐 | Q20: =IF($P$17=P20,TRUE,FALSE) -> FALSE | R20: 피로 | S20: =IF($R$17=R20,TRUE,FALSE) -> FALSE
J21: 충돌 | K21: =IF(J21=$J$17,TRUE,FALSE) -> TRUE | L21: 안전난간 | M21: =IF($L$17=L21,TRUE,FALSE) -> FALSE | N21: 무거운 짐 취급 | O21: =IF($N$17=N21,TRUE,FALSE) -> FALSE | P21: 위험을 보지 않음 | Q21: =IF($P$17=P21,TRUE,FALSE) -> FALSE | R21: 스트레스 | S21: =IF($R$17=R21,TRUE,FALSE) -> FALSE
J22: 낙하 | K22: =IF(J22=$J$17,TRUE,FALSE) -> FALSE | L22: 작업발판 | M22: FALSE | N22: 보호구 | O22: =IF($N$17=N22,TRUE,FALSE) -> FALSE | P22: 위험을 생각하지 않음 | Q22: =IF($P$17=P22,TRUE,FALSE) -> TRUE | R22: 자만심 | S22: =IF($R$17=R22,TRUE,FALSE) -> FALSE
J23: 비래 | K23: =IF(J23=$J$17,TRUE,FALSE) -> FALSE | L23: 개구부 | M23: FALSE | N23: 불안전한 자세 | O23: =IF($N$17=N23,TRUE,FALSE) -> FALSE
J24: 붕괴 | K24: =IF(J24=$J$17,TRUE,FALSE) -> FALSE | L24: 전기 | M24: FALSE | N24: 소통 미비 | O24: =IF($N$17=N24,TRUE,FALSE) -> FALSE
J25: 협착 | K25: =IF(J25=$J$17,TRUE,FALSE) -> FALSE | L25: 운전장비 | M25: =IF($L$17=L25,TRUE,FALSE) -> FALSE | N25: 평소 습관 | O25: =IF($N$17=N25,TRUE,FALSE) -> FALSE
J26: 감전 | K26: =IF(J26=$J$17,TRUE,FALSE) -> FALSE | L26: 설비 | M26: =IF($L$17=L26,TRUE,FALSE) -> FALSE | N26: 기타 | O26: =IF($N$17=N26,TRUE,FALSE) -> FALSE
D27: 불안전한 행동 : | J27: 요통 | K27: =IF(J27=$J$17,TRUE,FALSE) -> FALSE | L27: 정리정돈 | M27: =IF($L$17=L27,TRUE,FALSE) -> FALSE
J28: 화상/동상 | K28: =IF(J28=$J$17,TRUE,FALSE) -> FALSE | L28: 자연재해 | M28: =IF($L$17=L28,TRUE,FALSE) -> FALSE
J29: 기타 | K29: =IF(J29=$J$17,TRUE,FALSE) -> FALSE | L29: 기타 | M29: =IF($L$17=L29,TRUE,FALSE) -> FALSE
J30: 설비 사고 | K30: =IF(J30=$J$17,TRUE,FALSE) -> FALSE | L30: 계단 | M30: =IF($L$17=L30,TRUE,FALSE) -> FALSE
J31: 유해물질 접촉 | K31: =IF(J31=$J$17,TRUE,FALSE) -> FALSE | L31: 낙석 | M31: =IF($L$17=L31,TRUE,FALSE) -> FALSE
J32: 화재/ 폭발 | K32: =IF(J32=$J$17,TRUE,FALSE) -> FALSE | L32: 폭설/ 결빙 | M32: =IF($L$17=L32,TRUE,FALSE) -> FALSE
J33: 익사 | K33: =IF(J33=$J$17,TRUE,FALSE) -> FALSE | L33: 도구 및 장비 | M33: =IF($L$17=L33,TRUE,FALSE) -> FALSE
J34: 절단/ 찰과상 | K34: =IF(J34=$J$17,TRUE,FALSE) -> FALSE | L34: 동물/ 뱀/ 벌 | M34: =IF($L$17=L34,TRUE,FALSE) -> FALSE
A35: 사고 방지를 위해 | B35: ※ 보고자가 조치한 사항이 있는경우에 기록 해 주시기 바랍니다. | J35: 분류 불능 | K35: =IF(J35=$J$17,TRUE,FALSE) -> FALSE | L35: 제3자 | M35: =IF($L$17=L35,TRUE,FALSE) -> FALSE
